[2024-08-20 10:44:12 +0800] [257764] [INFO] Starting gunicorn 23.0.0
[2024-08-20 10:44:12 +0800] [257764] [INFO] Listening at: http://127.0.0.1:8000 (257764)
[2024-08-20 10:44:12 +0800] [257764] [INFO] Using worker: sync
[2024-08-20 10:44:12 +0800] [257765] [INFO] Booting worker with pid: 257765
[2024-08-20 10:44:12 +0800] [257766] [INFO] Booting worker with pid: 257766
[2024-08-20 10:44:12 +0800] [257767] [INFO] Booting worker with pid: 257767
Not Found: /account/signup_login/
Not Found: /account/signup_login/
Not Found: /account/signup_login/
Not Found: /account/signup_login/
Not Found: /account/signup_login/
Not Found: /account/signup_login/
Not Found: /account/signup_login/
Not Found: /account/signup_login/
Not Found: /account/signup_login/
Not Found: /account/signup_login/
Not Found: /account/signup_login/
Not Found: /account/signup_login/
Not Found: /account/signup_login/
Not Found: /account/signup_login/
Not Found: /account/signup_login/
Not Found: /account/signup_login/
/home/scs22/iGEM-2024-Coders/USTC-Software/Apps/forum/views.py:104: UnorderedObjectListWarning: Pagination may yield inconsistent results with an unordered object_list: <class 'Apps.forum.models.CourseResource'> QuerySet.
  paginator = Paginator(resources_list, 10)  # 每页显示10条记录
Internal Server Error: /forum/course_resources/
Traceback (most recent call last):
  File "/opt/miniconda3/envs/website/lib/python3.11/site-packages/django/db/backends/base/base.py", line 282, in ensure_connection
    self.connect()
  File "/opt/miniconda3/envs/website/lib/python3.11/site-packages/django/utils/asyncio.py", line 26, in inner
    return func(*args, **kwargs)
           ^^^^^^^^^^^^^^^^^^^^^
  File "/opt/miniconda3/envs/website/lib/python3.11/site-packages/django/db/backends/base/base.py", line 263, in connect
    self.connection = self.get_new_connection(conn_params)
                      ^^^^^^^^^^^^^^^^^^^^^^^^^^^^^^^^^^^^
  File "/opt/miniconda3/envs/website/lib/python3.11/site-packages/django/utils/asyncio.py", line 26, in inner
    return func(*args, **kwargs)
           ^^^^^^^^^^^^^^^^^^^^^
  File "/opt/miniconda3/envs/website/lib/python3.11/site-packages/django/db/backends/mysql/base.py", line 247, in get_new_connection
    connection = Database.connect(**conn_params)
                 ^^^^^^^^^^^^^^^^^^^^^^^^^^^^^^^
  File "/opt/miniconda3/envs/website/lib/python3.11/site-packages/pymysql/connections.py", line 361, in __init__
    self.connect()
  File "/opt/miniconda3/envs/website/lib/python3.11/site-packages/pymysql/connections.py", line 669, in connect
    self._request_authentication()
  File "/opt/miniconda3/envs/website/lib/python3.11/site-packages/pymysql/connections.py", line 957, in _request_authentication
    auth_packet = self._read_packet()
                  ^^^^^^^^^^^^^^^^^^^
  File "/opt/miniconda3/envs/website/lib/python3.11/site-packages/pymysql/connections.py", line 775, in _read_packet
    packet.raise_for_error()
  File "/opt/miniconda3/envs/website/lib/python3.11/site-packages/pymysql/protocol.py", line 219, in raise_for_error
    err.raise_mysql_exception(self._data)
  File "/opt/miniconda3/envs/website/lib/python3.11/site-packages/pymysql/err.py", line 150, in raise_mysql_exception
    raise errorclass(errno, errval)
pymysql.err.OperationalError: (1698, "Access denied for user 'root'@'localhost'")

The above exception was the direct cause of the following exception:

Traceback (most recent call last):
  File "/opt/miniconda3/envs/website/lib/python3.11/site-packages/django/core/handlers/exception.py", line 55, in inner
    response = get_response(request)
               ^^^^^^^^^^^^^^^^^^^^^
  File "/opt/miniconda3/envs/website/lib/python3.11/site-packages/django/core/handlers/base.py", line 197, in _get_response
    response = wrapped_callback(request, *callback_args, **callback_kwargs)
               ^^^^^^^^^^^^^^^^^^^^^^^^^^^^^^^^^^^^^^^^^^^^^^^^^^^^^^^^^^^^
  File "/home/scs22/iGEM-2024-Coders/USTC-Software/Apps/forum/views.py", line 106, in course_resources_index
    page_obj = paginator.get_page(page_number)
               ^^^^^^^^^^^^^^^^^^^^^^^^^^^^^^^
  File "/opt/miniconda3/envs/website/lib/python3.11/site-packages/django/core/paginator.py", line 66, in get_page
    number = self.validate_number(number)
             ^^^^^^^^^^^^^^^^^^^^^^^^^^^^
  File "/opt/miniconda3/envs/website/lib/python3.11/site-packages/django/core/paginator.py", line 53, in validate_number
    if number > self.num_pages:
                ^^^^^^^^^^^^^^
  File "/opt/miniconda3/envs/website/lib/python3.11/site-packages/django/utils/functional.py", line 57, in __get__
    res = instance.__dict__[self.name] = self.func(instance)
                                         ^^^^^^^^^^^^^^^^^^^
  File "/opt/miniconda3/envs/website/lib/python3.11/site-packages/django/core/paginator.py", line 102, in num_pages
    if self.count == 0 and not self.allow_empty_first_page:
       ^^^^^^^^^^
  File "/opt/miniconda3/envs/website/lib/python3.11/site-packages/django/utils/functional.py", line 57, in __get__
    res = instance.__dict__[self.name] = self.func(instance)
                                         ^^^^^^^^^^^^^^^^^^^
  File "/opt/miniconda3/envs/website/lib/python3.11/site-packages/django/core/paginator.py", line 96, in count
    return c()
           ^^^
  File "/opt/miniconda3/envs/website/lib/python3.11/site-packages/django/db/models/query.py", line 621, in count
    return self.query.get_count(using=self.db)
           ^^^^^^^^^^^^^^^^^^^^^^^^^^^^^^^^^^^
  File "/opt/miniconda3/envs/website/lib/python3.11/site-packages/django/db/models/sql/query.py", line 559, in get_count
    return obj.get_aggregation(using, ["__count"])["__count"]
           ^^^^^^^^^^^^^^^^^^^^^^^^^^^^^^^^^^^^^^^
  File "/opt/miniconda3/envs/website/lib/python3.11/site-packages/django/db/models/sql/query.py", line 544, in get_aggregation
    result = compiler.execute_sql(SINGLE)
             ^^^^^^^^^^^^^^^^^^^^^^^^^^^^
  File "/opt/miniconda3/envs/website/lib/python3.11/site-packages/django/db/models/sql/compiler.py", line 1393, in execute_sql
    cursor = self.connection.cursor()
             ^^^^^^^^^^^^^^^^^^^^^^^^
  File "/opt/miniconda3/envs/website/lib/python3.11/site-packages/django/utils/asyncio.py", line 26, in inner
    return func(*args, **kwargs)
           ^^^^^^^^^^^^^^^^^^^^^
  File "/opt/miniconda3/envs/website/lib/python3.11/site-packages/django/db/backends/base/base.py", line 323, in cursor
    return self._cursor()
           ^^^^^^^^^^^^^^
  File "/opt/miniconda3/envs/website/lib/python3.11/site-packages/django/db/backends/base/base.py", line 299, in _cursor
    self.ensure_connection()
  File "/opt/miniconda3/envs/website/lib/python3.11/site-packages/django/utils/asyncio.py", line 26, in inner
    return func(*args, **kwargs)
           ^^^^^^^^^^^^^^^^^^^^^
  File "/opt/miniconda3/envs/website/lib/python3.11/site-packages/django/db/backends/base/base.py", line 281, in ensure_connection
    with self.wrap_database_errors:
  File "/opt/miniconda3/envs/website/lib/python3.11/site-packages/django/db/utils.py", line 91, in __exit__
    raise dj_exc_value.with_traceback(traceback) from exc_value
  File "/opt/miniconda3/envs/website/lib/python3.11/site-packages/django/db/backends/base/base.py", line 282, in ensure_connection
    self.connect()
  File "/opt/miniconda3/envs/website/lib/python3.11/site-packages/django/utils/asyncio.py", line 26, in inner
    return func(*args, **kwargs)
           ^^^^^^^^^^^^^^^^^^^^^
  File "/opt/miniconda3/envs/website/lib/python3.11/site-packages/django/db/backends/base/base.py", line 263, in connect
    self.connection = self.get_new_connection(conn_params)
                      ^^^^^^^^^^^^^^^^^^^^^^^^^^^^^^^^^^^^
  File "/opt/miniconda3/envs/website/lib/python3.11/site-packages/django/utils/asyncio.py", line 26, in inner
    return func(*args, **kwargs)
           ^^^^^^^^^^^^^^^^^^^^^
  File "/opt/miniconda3/envs/website/lib/python3.11/site-packages/django/db/backends/mysql/base.py", line 247, in get_new_connection
    connection = Database.connect(**conn_params)
                 ^^^^^^^^^^^^^^^^^^^^^^^^^^^^^^^
  File "/opt/miniconda3/envs/website/lib/python3.11/site-packages/pymysql/connections.py", line 361, in __init__
    self.connect()
  File "/opt/miniconda3/envs/website/lib/python3.11/site-packages/pymysql/connections.py", line 669, in connect
    self._request_authentication()
  File "/opt/miniconda3/envs/website/lib/python3.11/site-packages/pymysql/connections.py", line 957, in _request_authentication
    auth_packet = self._read_packet()
                  ^^^^^^^^^^^^^^^^^^^
  File "/opt/miniconda3/envs/website/lib/python3.11/site-packages/pymysql/connections.py", line 775, in _read_packet
    packet.raise_for_error()
  File "/opt/miniconda3/envs/website/lib/python3.11/site-packages/pymysql/protocol.py", line 219, in raise_for_error
    err.raise_mysql_exception(self._data)
  File "/opt/miniconda3/envs/website/lib/python3.11/site-packages/pymysql/err.py", line 150, in raise_mysql_exception
    raise errorclass(errno, errval)
django.db.utils.OperationalError: (1698, "Access denied for user 'root'@'localhost'")
Internal Server Error: /forum/course_resources/
Traceback (most recent call last):
  File "/opt/miniconda3/envs/website/lib/python3.11/site-packages/django/db/backends/base/base.py", line 282, in ensure_connection
    self.connect()
  File "/opt/miniconda3/envs/website/lib/python3.11/site-packages/django/utils/asyncio.py", line 26, in inner
    return func(*args, **kwargs)
           ^^^^^^^^^^^^^^^^^^^^^
  File "/opt/miniconda3/envs/website/lib/python3.11/site-packages/django/db/backends/base/base.py", line 263, in connect
    self.connection = self.get_new_connection(conn_params)
                      ^^^^^^^^^^^^^^^^^^^^^^^^^^^^^^^^^^^^
  File "/opt/miniconda3/envs/website/lib/python3.11/site-packages/django/utils/asyncio.py", line 26, in inner
    return func(*args, **kwargs)
           ^^^^^^^^^^^^^^^^^^^^^
  File "/opt/miniconda3/envs/website/lib/python3.11/site-packages/django/db/backends/mysql/base.py", line 247, in get_new_connection
    connection = Database.connect(**conn_params)
                 ^^^^^^^^^^^^^^^^^^^^^^^^^^^^^^^
  File "/opt/miniconda3/envs/website/lib/python3.11/site-packages/pymysql/connections.py", line 361, in __init__
    self.connect()
  File "/opt/miniconda3/envs/website/lib/python3.11/site-packages/pymysql/connections.py", line 669, in connect
    self._request_authentication()
  File "/opt/miniconda3/envs/website/lib/python3.11/site-packages/pymysql/connections.py", line 957, in _request_authentication
    auth_packet = self._read_packet()
                  ^^^^^^^^^^^^^^^^^^^
  File "/opt/miniconda3/envs/website/lib/python3.11/site-packages/pymysql/connections.py", line 775, in _read_packet
    packet.raise_for_error()
  File "/opt/miniconda3/envs/website/lib/python3.11/site-packages/pymysql/protocol.py", line 219, in raise_for_error
    err.raise_mysql_exception(self._data)
  File "/opt/miniconda3/envs/website/lib/python3.11/site-packages/pymysql/err.py", line 150, in raise_mysql_exception
    raise errorclass(errno, errval)
pymysql.err.OperationalError: (1698, "Access denied for user 'root'@'localhost'")

The above exception was the direct cause of the following exception:

Traceback (most recent call last):
  File "/opt/miniconda3/envs/website/lib/python3.11/site-packages/django/core/handlers/exception.py", line 55, in inner
    response = get_response(request)
               ^^^^^^^^^^^^^^^^^^^^^
  File "/opt/miniconda3/envs/website/lib/python3.11/site-packages/django/core/handlers/base.py", line 197, in _get_response
    response = wrapped_callback(request, *callback_args, **callback_kwargs)
               ^^^^^^^^^^^^^^^^^^^^^^^^^^^^^^^^^^^^^^^^^^^^^^^^^^^^^^^^^^^^
  File "/home/scs22/iGEM-2024-Coders/USTC-Software/Apps/forum/views.py", line 106, in course_resources_index
    page_obj = paginator.get_page(page_number)
               ^^^^^^^^^^^^^^^^^^^^^^^^^^^^^^^
  File "/opt/miniconda3/envs/website/lib/python3.11/site-packages/django/core/paginator.py", line 66, in get_page
    number = self.validate_number(number)
             ^^^^^^^^^^^^^^^^^^^^^^^^^^^^
  File "/opt/miniconda3/envs/website/lib/python3.11/site-packages/django/core/paginator.py", line 53, in validate_number
    if number > self.num_pages:
                ^^^^^^^^^^^^^^
  File "/opt/miniconda3/envs/website/lib/python3.11/site-packages/django/utils/functional.py", line 57, in __get__
    res = instance.__dict__[self.name] = self.func(instance)
                                         ^^^^^^^^^^^^^^^^^^^
  File "/opt/miniconda3/envs/website/lib/python3.11/site-packages/django/core/paginator.py", line 102, in num_pages
    if self.count == 0 and not self.allow_empty_first_page:
       ^^^^^^^^^^
  File "/opt/miniconda3/envs/website/lib/python3.11/site-packages/django/utils/functional.py", line 57, in __get__
    res = instance.__dict__[self.name] = self.func(instance)
                                         ^^^^^^^^^^^^^^^^^^^
  File "/opt/miniconda3/envs/website/lib/python3.11/site-packages/django/core/paginator.py", line 96, in count
    return c()
           ^^^
  File "/opt/miniconda3/envs/website/lib/python3.11/site-packages/django/db/models/query.py", line 621, in count
    return self.query.get_count(using=self.db)
           ^^^^^^^^^^^^^^^^^^^^^^^^^^^^^^^^^^^
  File "/opt/miniconda3/envs/website/lib/python3.11/site-packages/django/db/models/sql/query.py", line 559, in get_count
    return obj.get_aggregation(using, ["__count"])["__count"]
           ^^^^^^^^^^^^^^^^^^^^^^^^^^^^^^^^^^^^^^^
  File "/opt/miniconda3/envs/website/lib/python3.11/site-packages/django/db/models/sql/query.py", line 544, in get_aggregation
    result = compiler.execute_sql(SINGLE)
             ^^^^^^^^^^^^^^^^^^^^^^^^^^^^
  File "/opt/miniconda3/envs/website/lib/python3.11/site-packages/django/db/models/sql/compiler.py", line 1393, in execute_sql
    cursor = self.connection.cursor()
             ^^^^^^^^^^^^^^^^^^^^^^^^
  File "/opt/miniconda3/envs/website/lib/python3.11/site-packages/django/utils/asyncio.py", line 26, in inner
    return func(*args, **kwargs)
           ^^^^^^^^^^^^^^^^^^^^^
  File "/opt/miniconda3/envs/website/lib/python3.11/site-packages/django/db/backends/base/base.py", line 323, in cursor
    return self._cursor()
           ^^^^^^^^^^^^^^
  File "/opt/miniconda3/envs/website/lib/python3.11/site-packages/django/db/backends/base/base.py", line 299, in _cursor
    self.ensure_connection()
  File "/opt/miniconda3/envs/website/lib/python3.11/site-packages/django/utils/asyncio.py", line 26, in inner
    return func(*args, **kwargs)
           ^^^^^^^^^^^^^^^^^^^^^
  File "/opt/miniconda3/envs/website/lib/python3.11/site-packages/django/db/backends/base/base.py", line 281, in ensure_connection
    with self.wrap_database_errors:
  File "/opt/miniconda3/envs/website/lib/python3.11/site-packages/django/db/utils.py", line 91, in __exit__
    raise dj_exc_value.with_traceback(traceback) from exc_value
  File "/opt/miniconda3/envs/website/lib/python3.11/site-packages/django/db/backends/base/base.py", line 282, in ensure_connection
    self.connect()
  File "/opt/miniconda3/envs/website/lib/python3.11/site-packages/django/utils/asyncio.py", line 26, in inner
    return func(*args, **kwargs)
           ^^^^^^^^^^^^^^^^^^^^^
  File "/opt/miniconda3/envs/website/lib/python3.11/site-packages/django/db/backends/base/base.py", line 263, in connect
    self.connection = self.get_new_connection(conn_params)
                      ^^^^^^^^^^^^^^^^^^^^^^^^^^^^^^^^^^^^
  File "/opt/miniconda3/envs/website/lib/python3.11/site-packages/django/utils/asyncio.py", line 26, in inner
    return func(*args, **kwargs)
           ^^^^^^^^^^^^^^^^^^^^^
  File "/opt/miniconda3/envs/website/lib/python3.11/site-packages/django/db/backends/mysql/base.py", line 247, in get_new_connection
    connection = Database.connect(**conn_params)
                 ^^^^^^^^^^^^^^^^^^^^^^^^^^^^^^^
  File "/opt/miniconda3/envs/website/lib/python3.11/site-packages/pymysql/connections.py", line 361, in __init__
    self.connect()
  File "/opt/miniconda3/envs/website/lib/python3.11/site-packages/pymysql/connections.py", line 669, in connect
    self._request_authentication()
  File "/opt/miniconda3/envs/website/lib/python3.11/site-packages/pymysql/connections.py", line 957, in _request_authentication
    auth_packet = self._read_packet()
                  ^^^^^^^^^^^^^^^^^^^
  File "/opt/miniconda3/envs/website/lib/python3.11/site-packages/pymysql/connections.py", line 775, in _read_packet
    packet.raise_for_error()
  File "/opt/miniconda3/envs/website/lib/python3.11/site-packages/pymysql/protocol.py", line 219, in raise_for_error
    err.raise_mysql_exception(self._data)
  File "/opt/miniconda3/envs/website/lib/python3.11/site-packages/pymysql/err.py", line 150, in raise_mysql_exception
    raise errorclass(errno, errval)
django.db.utils.OperationalError: (1698, "Access denied for user 'root'@'localhost'")
Internal Server Error: /forum/course_resources/
Traceback (most recent call last):
  File "/opt/miniconda3/envs/website/lib/python3.11/site-packages/django/db/backends/base/base.py", line 282, in ensure_connection
    self.connect()
  File "/opt/miniconda3/envs/website/lib/python3.11/site-packages/django/utils/asyncio.py", line 26, in inner
    return func(*args, **kwargs)
           ^^^^^^^^^^^^^^^^^^^^^
  File "/opt/miniconda3/envs/website/lib/python3.11/site-packages/django/db/backends/base/base.py", line 263, in connect
    self.connection = self.get_new_connection(conn_params)
                      ^^^^^^^^^^^^^^^^^^^^^^^^^^^^^^^^^^^^
  File "/opt/miniconda3/envs/website/lib/python3.11/site-packages/django/utils/asyncio.py", line 26, in inner
    return func(*args, **kwargs)
           ^^^^^^^^^^^^^^^^^^^^^
  File "/opt/miniconda3/envs/website/lib/python3.11/site-packages/django/db/backends/mysql/base.py", line 247, in get_new_connection
    connection = Database.connect(**conn_params)
                 ^^^^^^^^^^^^^^^^^^^^^^^^^^^^^^^
  File "/opt/miniconda3/envs/website/lib/python3.11/site-packages/pymysql/connections.py", line 361, in __init__
    self.connect()
  File "/opt/miniconda3/envs/website/lib/python3.11/site-packages/pymysql/connections.py", line 669, in connect
    self._request_authentication()
  File "/opt/miniconda3/envs/website/lib/python3.11/site-packages/pymysql/connections.py", line 957, in _request_authentication
    auth_packet = self._read_packet()
                  ^^^^^^^^^^^^^^^^^^^
  File "/opt/miniconda3/envs/website/lib/python3.11/site-packages/pymysql/connections.py", line 775, in _read_packet
    packet.raise_for_error()
  File "/opt/miniconda3/envs/website/lib/python3.11/site-packages/pymysql/protocol.py", line 219, in raise_for_error
    err.raise_mysql_exception(self._data)
  File "/opt/miniconda3/envs/website/lib/python3.11/site-packages/pymysql/err.py", line 150, in raise_mysql_exception
    raise errorclass(errno, errval)
pymysql.err.OperationalError: (1698, "Access denied for user 'root'@'localhost'")

The above exception was the direct cause of the following exception:

Traceback (most recent call last):
  File "/opt/miniconda3/envs/website/lib/python3.11/site-packages/django/core/handlers/exception.py", line 55, in inner
    response = get_response(request)
               ^^^^^^^^^^^^^^^^^^^^^
  File "/opt/miniconda3/envs/website/lib/python3.11/site-packages/django/core/handlers/base.py", line 197, in _get_response
    response = wrapped_callback(request, *callback_args, **callback_kwargs)
               ^^^^^^^^^^^^^^^^^^^^^^^^^^^^^^^^^^^^^^^^^^^^^^^^^^^^^^^^^^^^
  File "/home/scs22/iGEM-2024-Coders/USTC-Software/Apps/forum/views.py", line 106, in course_resources_index
    page_obj = paginator.get_page(page_number)
               ^^^^^^^^^^^^^^^^^^^^^^^^^^^^^^^
  File "/opt/miniconda3/envs/website/lib/python3.11/site-packages/django/core/paginator.py", line 66, in get_page
    number = self.validate_number(number)
             ^^^^^^^^^^^^^^^^^^^^^^^^^^^^
  File "/opt/miniconda3/envs/website/lib/python3.11/site-packages/django/core/paginator.py", line 53, in validate_number
    if number > self.num_pages:
                ^^^^^^^^^^^^^^
  File "/opt/miniconda3/envs/website/lib/python3.11/site-packages/django/utils/functional.py", line 57, in __get__
    res = instance.__dict__[self.name] = self.func(instance)
                                         ^^^^^^^^^^^^^^^^^^^
  File "/opt/miniconda3/envs/website/lib/python3.11/site-packages/django/core/paginator.py", line 102, in num_pages
    if self.count == 0 and not self.allow_empty_first_page:
       ^^^^^^^^^^
  File "/opt/miniconda3/envs/website/lib/python3.11/site-packages/django/utils/functional.py", line 57, in __get__
    res = instance.__dict__[self.name] = self.func(instance)
                                         ^^^^^^^^^^^^^^^^^^^
  File "/opt/miniconda3/envs/website/lib/python3.11/site-packages/django/core/paginator.py", line 96, in count
    return c()
           ^^^
  File "/opt/miniconda3/envs/website/lib/python3.11/site-packages/django/db/models/query.py", line 621, in count
    return self.query.get_count(using=self.db)
           ^^^^^^^^^^^^^^^^^^^^^^^^^^^^^^^^^^^
  File "/opt/miniconda3/envs/website/lib/python3.11/site-packages/django/db/models/sql/query.py", line 559, in get_count
    return obj.get_aggregation(using, ["__count"])["__count"]
           ^^^^^^^^^^^^^^^^^^^^^^^^^^^^^^^^^^^^^^^
  File "/opt/miniconda3/envs/website/lib/python3.11/site-packages/django/db/models/sql/query.py", line 544, in get_aggregation
    result = compiler.execute_sql(SINGLE)
             ^^^^^^^^^^^^^^^^^^^^^^^^^^^^
  File "/opt/miniconda3/envs/website/lib/python3.11/site-packages/django/db/models/sql/compiler.py", line 1393, in execute_sql
    cursor = self.connection.cursor()
             ^^^^^^^^^^^^^^^^^^^^^^^^
  File "/opt/miniconda3/envs/website/lib/python3.11/site-packages/django/utils/asyncio.py", line 26, in inner
    return func(*args, **kwargs)
           ^^^^^^^^^^^^^^^^^^^^^
  File "/opt/miniconda3/envs/website/lib/python3.11/site-packages/django/db/backends/base/base.py", line 323, in cursor
    return self._cursor()
           ^^^^^^^^^^^^^^
  File "/opt/miniconda3/envs/website/lib/python3.11/site-packages/django/db/backends/base/base.py", line 299, in _cursor
    self.ensure_connection()
  File "/opt/miniconda3/envs/website/lib/python3.11/site-packages/django/utils/asyncio.py", line 26, in inner
    return func(*args, **kwargs)
           ^^^^^^^^^^^^^^^^^^^^^
  File "/opt/miniconda3/envs/website/lib/python3.11/site-packages/django/db/backends/base/base.py", line 281, in ensure_connection
    with self.wrap_database_errors:
  File "/opt/miniconda3/envs/website/lib/python3.11/site-packages/django/db/utils.py", line 91, in __exit__
    raise dj_exc_value.with_traceback(traceback) from exc_value
  File "/opt/miniconda3/envs/website/lib/python3.11/site-packages/django/db/backends/base/base.py", line 282, in ensure_connection
    self.connect()
  File "/opt/miniconda3/envs/website/lib/python3.11/site-packages/django/utils/asyncio.py", line 26, in inner
    return func(*args, **kwargs)
           ^^^^^^^^^^^^^^^^^^^^^
  File "/opt/miniconda3/envs/website/lib/python3.11/site-packages/django/db/backends/base/base.py", line 263, in connect
    self.connection = self.get_new_connection(conn_params)
                      ^^^^^^^^^^^^^^^^^^^^^^^^^^^^^^^^^^^^
  File "/opt/miniconda3/envs/website/lib/python3.11/site-packages/django/utils/asyncio.py", line 26, in inner
    return func(*args, **kwargs)
           ^^^^^^^^^^^^^^^^^^^^^
  File "/opt/miniconda3/envs/website/lib/python3.11/site-packages/django/db/backends/mysql/base.py", line 247, in get_new_connection
    connection = Database.connect(**conn_params)
                 ^^^^^^^^^^^^^^^^^^^^^^^^^^^^^^^
  File "/opt/miniconda3/envs/website/lib/python3.11/site-packages/pymysql/connections.py", line 361, in __init__
    self.connect()
  File "/opt/miniconda3/envs/website/lib/python3.11/site-packages/pymysql/connections.py", line 669, in connect
    self._request_authentication()
  File "/opt/miniconda3/envs/website/lib/python3.11/site-packages/pymysql/connections.py", line 957, in _request_authentication
    auth_packet = self._read_packet()
                  ^^^^^^^^^^^^^^^^^^^
  File "/opt/miniconda3/envs/website/lib/python3.11/site-packages/pymysql/connections.py", line 775, in _read_packet
    packet.raise_for_error()
  File "/opt/miniconda3/envs/website/lib/python3.11/site-packages/pymysql/protocol.py", line 219, in raise_for_error
    err.raise_mysql_exception(self._data)
  File "/opt/miniconda3/envs/website/lib/python3.11/site-packages/pymysql/err.py", line 150, in raise_mysql_exception
    raise errorclass(errno, errval)
django.db.utils.OperationalError: (1698, "Access denied for user 'root'@'localhost'")
/home/scs22/iGEM-2024-Coders/USTC-Software/Apps/forum/views.py:104: UnorderedObjectListWarning: Pagination may yield inconsistent results with an unordered object_list: <class 'Apps.forum.models.CourseResource'> QuerySet.
  paginator = Paginator(resources_list, 10)  # 每页显示10条记录
Internal Server Error: /forum/course_resources/
Traceback (most recent call last):
  File "/opt/miniconda3/envs/website/lib/python3.11/site-packages/django/db/backends/base/base.py", line 282, in ensure_connection
    self.connect()
  File "/opt/miniconda3/envs/website/lib/python3.11/site-packages/django/utils/asyncio.py", line 26, in inner
    return func(*args, **kwargs)
           ^^^^^^^^^^^^^^^^^^^^^
  File "/opt/miniconda3/envs/website/lib/python3.11/site-packages/django/db/backends/base/base.py", line 263, in connect
    self.connection = self.get_new_connection(conn_params)
                      ^^^^^^^^^^^^^^^^^^^^^^^^^^^^^^^^^^^^
  File "/opt/miniconda3/envs/website/lib/python3.11/site-packages/django/utils/asyncio.py", line 26, in inner
    return func(*args, **kwargs)
           ^^^^^^^^^^^^^^^^^^^^^
  File "/opt/miniconda3/envs/website/lib/python3.11/site-packages/django/db/backends/mysql/base.py", line 247, in get_new_connection
    connection = Database.connect(**conn_params)
                 ^^^^^^^^^^^^^^^^^^^^^^^^^^^^^^^
  File "/opt/miniconda3/envs/website/lib/python3.11/site-packages/pymysql/connections.py", line 361, in __init__
    self.connect()
  File "/opt/miniconda3/envs/website/lib/python3.11/site-packages/pymysql/connections.py", line 669, in connect
    self._request_authentication()
  File "/opt/miniconda3/envs/website/lib/python3.11/site-packages/pymysql/connections.py", line 957, in _request_authentication
    auth_packet = self._read_packet()
                  ^^^^^^^^^^^^^^^^^^^
  File "/opt/miniconda3/envs/website/lib/python3.11/site-packages/pymysql/connections.py", line 775, in _read_packet
    packet.raise_for_error()
  File "/opt/miniconda3/envs/website/lib/python3.11/site-packages/pymysql/protocol.py", line 219, in raise_for_error
    err.raise_mysql_exception(self._data)
  File "/opt/miniconda3/envs/website/lib/python3.11/site-packages/pymysql/err.py", line 150, in raise_mysql_exception
    raise errorclass(errno, errval)
pymysql.err.OperationalError: (1698, "Access denied for user 'root'@'localhost'")

The above exception was the direct cause of the following exception:

Traceback (most recent call last):
  File "/opt/miniconda3/envs/website/lib/python3.11/site-packages/django/core/handlers/exception.py", line 55, in inner
    response = get_response(request)
               ^^^^^^^^^^^^^^^^^^^^^
  File "/opt/miniconda3/envs/website/lib/python3.11/site-packages/django/core/handlers/base.py", line 197, in _get_response
    response = wrapped_callback(request, *callback_args, **callback_kwargs)
               ^^^^^^^^^^^^^^^^^^^^^^^^^^^^^^^^^^^^^^^^^^^^^^^^^^^^^^^^^^^^
  File "/home/scs22/iGEM-2024-Coders/USTC-Software/Apps/forum/views.py", line 106, in course_resources_index
    page_obj = paginator.get_page(page_number)
               ^^^^^^^^^^^^^^^^^^^^^^^^^^^^^^^
  File "/opt/miniconda3/envs/website/lib/python3.11/site-packages/django/core/paginator.py", line 66, in get_page
    number = self.validate_number(number)
             ^^^^^^^^^^^^^^^^^^^^^^^^^^^^
  File "/opt/miniconda3/envs/website/lib/python3.11/site-packages/django/core/paginator.py", line 53, in validate_number
    if number > self.num_pages:
                ^^^^^^^^^^^^^^
  File "/opt/miniconda3/envs/website/lib/python3.11/site-packages/django/utils/functional.py", line 57, in __get__
    res = instance.__dict__[self.name] = self.func(instance)
                                         ^^^^^^^^^^^^^^^^^^^
  File "/opt/miniconda3/envs/website/lib/python3.11/site-packages/django/core/paginator.py", line 102, in num_pages
    if self.count == 0 and not self.allow_empty_first_page:
       ^^^^^^^^^^
  File "/opt/miniconda3/envs/website/lib/python3.11/site-packages/django/utils/functional.py", line 57, in __get__
    res = instance.__dict__[self.name] = self.func(instance)
                                         ^^^^^^^^^^^^^^^^^^^
  File "/opt/miniconda3/envs/website/lib/python3.11/site-packages/django/core/paginator.py", line 96, in count
    return c()
           ^^^
  File "/opt/miniconda3/envs/website/lib/python3.11/site-packages/django/db/models/query.py", line 621, in count
    return self.query.get_count(using=self.db)
           ^^^^^^^^^^^^^^^^^^^^^^^^^^^^^^^^^^^
  File "/opt/miniconda3/envs/website/lib/python3.11/site-packages/django/db/models/sql/query.py", line 559, in get_count
    return obj.get_aggregation(using, ["__count"])["__count"]
           ^^^^^^^^^^^^^^^^^^^^^^^^^^^^^^^^^^^^^^^
  File "/opt/miniconda3/envs/website/lib/python3.11/site-packages/django/db/models/sql/query.py", line 544, in get_aggregation
    result = compiler.execute_sql(SINGLE)
             ^^^^^^^^^^^^^^^^^^^^^^^^^^^^
  File "/opt/miniconda3/envs/website/lib/python3.11/site-packages/django/db/models/sql/compiler.py", line 1393, in execute_sql
    cursor = self.connection.cursor()
             ^^^^^^^^^^^^^^^^^^^^^^^^
  File "/opt/miniconda3/envs/website/lib/python3.11/site-packages/django/utils/asyncio.py", line 26, in inner
    return func(*args, **kwargs)
           ^^^^^^^^^^^^^^^^^^^^^
  File "/opt/miniconda3/envs/website/lib/python3.11/site-packages/django/db/backends/base/base.py", line 323, in cursor
    return self._cursor()
           ^^^^^^^^^^^^^^
  File "/opt/miniconda3/envs/website/lib/python3.11/site-packages/django/db/backends/base/base.py", line 299, in _cursor
    self.ensure_connection()
  File "/opt/miniconda3/envs/website/lib/python3.11/site-packages/django/utils/asyncio.py", line 26, in inner
    return func(*args, **kwargs)
           ^^^^^^^^^^^^^^^^^^^^^
  File "/opt/miniconda3/envs/website/lib/python3.11/site-packages/django/db/backends/base/base.py", line 281, in ensure_connection
    with self.wrap_database_errors:
  File "/opt/miniconda3/envs/website/lib/python3.11/site-packages/django/db/utils.py", line 91, in __exit__
    raise dj_exc_value.with_traceback(traceback) from exc_value
  File "/opt/miniconda3/envs/website/lib/python3.11/site-packages/django/db/backends/base/base.py", line 282, in ensure_connection
    self.connect()
  File "/opt/miniconda3/envs/website/lib/python3.11/site-packages/django/utils/asyncio.py", line 26, in inner
    return func(*args, **kwargs)
           ^^^^^^^^^^^^^^^^^^^^^
  File "/opt/miniconda3/envs/website/lib/python3.11/site-packages/django/db/backends/base/base.py", line 263, in connect
    self.connection = self.get_new_connection(conn_params)
                      ^^^^^^^^^^^^^^^^^^^^^^^^^^^^^^^^^^^^
  File "/opt/miniconda3/envs/website/lib/python3.11/site-packages/django/utils/asyncio.py", line 26, in inner
    return func(*args, **kwargs)
           ^^^^^^^^^^^^^^^^^^^^^
  File "/opt/miniconda3/envs/website/lib/python3.11/site-packages/django/db/backends/mysql/base.py", line 247, in get_new_connection
    connection = Database.connect(**conn_params)
                 ^^^^^^^^^^^^^^^^^^^^^^^^^^^^^^^
  File "/opt/miniconda3/envs/website/lib/python3.11/site-packages/pymysql/connections.py", line 361, in __init__
    self.connect()
  File "/opt/miniconda3/envs/website/lib/python3.11/site-packages/pymysql/connections.py", line 669, in connect
    self._request_authentication()
  File "/opt/miniconda3/envs/website/lib/python3.11/site-packages/pymysql/connections.py", line 957, in _request_authentication
    auth_packet = self._read_packet()
                  ^^^^^^^^^^^^^^^^^^^
  File "/opt/miniconda3/envs/website/lib/python3.11/site-packages/pymysql/connections.py", line 775, in _read_packet
    packet.raise_for_error()
  File "/opt/miniconda3/envs/website/lib/python3.11/site-packages/pymysql/protocol.py", line 219, in raise_for_error
    err.raise_mysql_exception(self._data)
  File "/opt/miniconda3/envs/website/lib/python3.11/site-packages/pymysql/err.py", line 150, in raise_mysql_exception
    raise errorclass(errno, errval)
django.db.utils.OperationalError: (1698, "Access denied for user 'root'@'localhost'")
/home/scs22/iGEM-2024-Coders/USTC-Software/Apps/forum/views.py:104: UnorderedObjectListWarning: Pagination may yield inconsistent results with an unordered object_list: <class 'Apps.forum.models.CourseResource'> QuerySet.
  paginator = Paginator(resources_list, 10)  # 每页显示10条记录
Internal Server Error: /forum/course_resources/
Traceback (most recent call last):
  File "/opt/miniconda3/envs/website/lib/python3.11/site-packages/django/db/backends/base/base.py", line 282, in ensure_connection
    self.connect()
  File "/opt/miniconda3/envs/website/lib/python3.11/site-packages/django/utils/asyncio.py", line 26, in inner
    return func(*args, **kwargs)
           ^^^^^^^^^^^^^^^^^^^^^
  File "/opt/miniconda3/envs/website/lib/python3.11/site-packages/django/db/backends/base/base.py", line 263, in connect
    self.connection = self.get_new_connection(conn_params)
                      ^^^^^^^^^^^^^^^^^^^^^^^^^^^^^^^^^^^^
  File "/opt/miniconda3/envs/website/lib/python3.11/site-packages/django/utils/asyncio.py", line 26, in inner
    return func(*args, **kwargs)
           ^^^^^^^^^^^^^^^^^^^^^
  File "/opt/miniconda3/envs/website/lib/python3.11/site-packages/django/db/backends/mysql/base.py", line 247, in get_new_connection
    connection = Database.connect(**conn_params)
                 ^^^^^^^^^^^^^^^^^^^^^^^^^^^^^^^
  File "/opt/miniconda3/envs/website/lib/python3.11/site-packages/pymysql/connections.py", line 361, in __init__
    self.connect()
  File "/opt/miniconda3/envs/website/lib/python3.11/site-packages/pymysql/connections.py", line 669, in connect
    self._request_authentication()
  File "/opt/miniconda3/envs/website/lib/python3.11/site-packages/pymysql/connections.py", line 957, in _request_authentication
    auth_packet = self._read_packet()
                  ^^^^^^^^^^^^^^^^^^^
  File "/opt/miniconda3/envs/website/lib/python3.11/site-packages/pymysql/connections.py", line 775, in _read_packet
    packet.raise_for_error()
  File "/opt/miniconda3/envs/website/lib/python3.11/site-packages/pymysql/protocol.py", line 219, in raise_for_error
    err.raise_mysql_exception(self._data)
  File "/opt/miniconda3/envs/website/lib/python3.11/site-packages/pymysql/err.py", line 150, in raise_mysql_exception
    raise errorclass(errno, errval)
pymysql.err.OperationalError: (1698, "Access denied for user 'root'@'localhost'")

The above exception was the direct cause of the following exception:

Traceback (most recent call last):
  File "/opt/miniconda3/envs/website/lib/python3.11/site-packages/django/core/handlers/exception.py", line 55, in inner
    response = get_response(request)
               ^^^^^^^^^^^^^^^^^^^^^
  File "/opt/miniconda3/envs/website/lib/python3.11/site-packages/django/core/handlers/base.py", line 197, in _get_response
    response = wrapped_callback(request, *callback_args, **callback_kwargs)
               ^^^^^^^^^^^^^^^^^^^^^^^^^^^^^^^^^^^^^^^^^^^^^^^^^^^^^^^^^^^^
  File "/home/scs22/iGEM-2024-Coders/USTC-Software/Apps/forum/views.py", line 106, in course_resources_index
    page_obj = paginator.get_page(page_number)
               ^^^^^^^^^^^^^^^^^^^^^^^^^^^^^^^
  File "/opt/miniconda3/envs/website/lib/python3.11/site-packages/django/core/paginator.py", line 66, in get_page
    number = self.validate_number(number)
             ^^^^^^^^^^^^^^^^^^^^^^^^^^^^
  File "/opt/miniconda3/envs/website/lib/python3.11/site-packages/django/core/paginator.py", line 53, in validate_number
    if number > self.num_pages:
                ^^^^^^^^^^^^^^
  File "/opt/miniconda3/envs/website/lib/python3.11/site-packages/django/utils/functional.py", line 57, in __get__
    res = instance.__dict__[self.name] = self.func(instance)
                                         ^^^^^^^^^^^^^^^^^^^
  File "/opt/miniconda3/envs/website/lib/python3.11/site-packages/django/core/paginator.py", line 102, in num_pages
    if self.count == 0 and not self.allow_empty_first_page:
       ^^^^^^^^^^
  File "/opt/miniconda3/envs/website/lib/python3.11/site-packages/django/utils/functional.py", line 57, in __get__
    res = instance.__dict__[self.name] = self.func(instance)
                                         ^^^^^^^^^^^^^^^^^^^
  File "/opt/miniconda3/envs/website/lib/python3.11/site-packages/django/core/paginator.py", line 96, in count
    return c()
           ^^^
  File "/opt/miniconda3/envs/website/lib/python3.11/site-packages/django/db/models/query.py", line 621, in count
    return self.query.get_count(using=self.db)
           ^^^^^^^^^^^^^^^^^^^^^^^^^^^^^^^^^^^
  File "/opt/miniconda3/envs/website/lib/python3.11/site-packages/django/db/models/sql/query.py", line 559, in get_count
    return obj.get_aggregation(using, ["__count"])["__count"]
           ^^^^^^^^^^^^^^^^^^^^^^^^^^^^^^^^^^^^^^^
  File "/opt/miniconda3/envs/website/lib/python3.11/site-packages/django/db/models/sql/query.py", line 544, in get_aggregation
    result = compiler.execute_sql(SINGLE)
             ^^^^^^^^^^^^^^^^^^^^^^^^^^^^
  File "/opt/miniconda3/envs/website/lib/python3.11/site-packages/django/db/models/sql/compiler.py", line 1393, in execute_sql
    cursor = self.connection.cursor()
             ^^^^^^^^^^^^^^^^^^^^^^^^
  File "/opt/miniconda3/envs/website/lib/python3.11/site-packages/django/utils/asyncio.py", line 26, in inner
    return func(*args, **kwargs)
           ^^^^^^^^^^^^^^^^^^^^^
  File "/opt/miniconda3/envs/website/lib/python3.11/site-packages/django/db/backends/base/base.py", line 323, in cursor
    return self._cursor()
           ^^^^^^^^^^^^^^
  File "/opt/miniconda3/envs/website/lib/python3.11/site-packages/django/db/backends/base/base.py", line 299, in _cursor
    self.ensure_connection()
  File "/opt/miniconda3/envs/website/lib/python3.11/site-packages/django/utils/asyncio.py", line 26, in inner
    return func(*args, **kwargs)
           ^^^^^^^^^^^^^^^^^^^^^
  File "/opt/miniconda3/envs/website/lib/python3.11/site-packages/django/db/backends/base/base.py", line 281, in ensure_connection
    with self.wrap_database_errors:
  File "/opt/miniconda3/envs/website/lib/python3.11/site-packages/django/db/utils.py", line 91, in __exit__
    raise dj_exc_value.with_traceback(traceback) from exc_value
  File "/opt/miniconda3/envs/website/lib/python3.11/site-packages/django/db/backends/base/base.py", line 282, in ensure_connection
    self.connect()
  File "/opt/miniconda3/envs/website/lib/python3.11/site-packages/django/utils/asyncio.py", line 26, in inner
    return func(*args, **kwargs)
           ^^^^^^^^^^^^^^^^^^^^^
  File "/opt/miniconda3/envs/website/lib/python3.11/site-packages/django/db/backends/base/base.py", line 263, in connect
    self.connection = self.get_new_connection(conn_params)
                      ^^^^^^^^^^^^^^^^^^^^^^^^^^^^^^^^^^^^
  File "/opt/miniconda3/envs/website/lib/python3.11/site-packages/django/utils/asyncio.py", line 26, in inner
    return func(*args, **kwargs)
           ^^^^^^^^^^^^^^^^^^^^^
  File "/opt/miniconda3/envs/website/lib/python3.11/site-packages/django/db/backends/mysql/base.py", line 247, in get_new_connection
    connection = Database.connect(**conn_params)
                 ^^^^^^^^^^^^^^^^^^^^^^^^^^^^^^^
  File "/opt/miniconda3/envs/website/lib/python3.11/site-packages/pymysql/connections.py", line 361, in __init__
    self.connect()
  File "/opt/miniconda3/envs/website/lib/python3.11/site-packages/pymysql/connections.py", line 669, in connect
    self._request_authentication()
  File "/opt/miniconda3/envs/website/lib/python3.11/site-packages/pymysql/connections.py", line 957, in _request_authentication
    auth_packet = self._read_packet()
                  ^^^^^^^^^^^^^^^^^^^
  File "/opt/miniconda3/envs/website/lib/python3.11/site-packages/pymysql/connections.py", line 775, in _read_packet
    packet.raise_for_error()
  File "/opt/miniconda3/envs/website/lib/python3.11/site-packages/pymysql/protocol.py", line 219, in raise_for_error
    err.raise_mysql_exception(self._data)
  File "/opt/miniconda3/envs/website/lib/python3.11/site-packages/pymysql/err.py", line 150, in raise_mysql_exception
    raise errorclass(errno, errval)
django.db.utils.OperationalError: (1698, "Access denied for user 'root'@'localhost'")
Not Found: /shell
Internal Server Error: /forum/course_resources/
Traceback (most recent call last):
  File "/opt/miniconda3/envs/website/lib/python3.11/site-packages/django/db/backends/base/base.py", line 282, in ensure_connection
    self.connect()
  File "/opt/miniconda3/envs/website/lib/python3.11/site-packages/django/utils/asyncio.py", line 26, in inner
    return func(*args, **kwargs)
           ^^^^^^^^^^^^^^^^^^^^^
  File "/opt/miniconda3/envs/website/lib/python3.11/site-packages/django/db/backends/base/base.py", line 263, in connect
    self.connection = self.get_new_connection(conn_params)
                      ^^^^^^^^^^^^^^^^^^^^^^^^^^^^^^^^^^^^
  File "/opt/miniconda3/envs/website/lib/python3.11/site-packages/django/utils/asyncio.py", line 26, in inner
    return func(*args, **kwargs)
           ^^^^^^^^^^^^^^^^^^^^^
  File "/opt/miniconda3/envs/website/lib/python3.11/site-packages/django/db/backends/mysql/base.py", line 247, in get_new_connection
    connection = Database.connect(**conn_params)
                 ^^^^^^^^^^^^^^^^^^^^^^^^^^^^^^^
  File "/opt/miniconda3/envs/website/lib/python3.11/site-packages/pymysql/connections.py", line 361, in __init__
    self.connect()
  File "/opt/miniconda3/envs/website/lib/python3.11/site-packages/pymysql/connections.py", line 669, in connect
    self._request_authentication()
  File "/opt/miniconda3/envs/website/lib/python3.11/site-packages/pymysql/connections.py", line 957, in _request_authentication
    auth_packet = self._read_packet()
                  ^^^^^^^^^^^^^^^^^^^
  File "/opt/miniconda3/envs/website/lib/python3.11/site-packages/pymysql/connections.py", line 775, in _read_packet
    packet.raise_for_error()
  File "/opt/miniconda3/envs/website/lib/python3.11/site-packages/pymysql/protocol.py", line 219, in raise_for_error
    err.raise_mysql_exception(self._data)
  File "/opt/miniconda3/envs/website/lib/python3.11/site-packages/pymysql/err.py", line 150, in raise_mysql_exception
    raise errorclass(errno, errval)
pymysql.err.OperationalError: (1698, "Access denied for user 'root'@'localhost'")

The above exception was the direct cause of the following exception:

Traceback (most recent call last):
  File "/opt/miniconda3/envs/website/lib/python3.11/site-packages/django/core/handlers/exception.py", line 55, in inner
    response = get_response(request)
               ^^^^^^^^^^^^^^^^^^^^^
  File "/opt/miniconda3/envs/website/lib/python3.11/site-packages/django/core/handlers/base.py", line 197, in _get_response
    response = wrapped_callback(request, *callback_args, **callback_kwargs)
               ^^^^^^^^^^^^^^^^^^^^^^^^^^^^^^^^^^^^^^^^^^^^^^^^^^^^^^^^^^^^
  File "/home/scs22/iGEM-2024-Coders/USTC-Software/Apps/forum/views.py", line 106, in course_resources_index
    page_obj = paginator.get_page(page_number)
               ^^^^^^^^^^^^^^^^^^^^^^^^^^^^^^^
  File "/opt/miniconda3/envs/website/lib/python3.11/site-packages/django/core/paginator.py", line 66, in get_page
    number = self.validate_number(number)
             ^^^^^^^^^^^^^^^^^^^^^^^^^^^^
  File "/opt/miniconda3/envs/website/lib/python3.11/site-packages/django/core/paginator.py", line 53, in validate_number
    if number > self.num_pages:
                ^^^^^^^^^^^^^^
  File "/opt/miniconda3/envs/website/lib/python3.11/site-packages/django/utils/functional.py", line 57, in __get__
    res = instance.__dict__[self.name] = self.func(instance)
                                         ^^^^^^^^^^^^^^^^^^^
  File "/opt/miniconda3/envs/website/lib/python3.11/site-packages/django/core/paginator.py", line 102, in num_pages
    if self.count == 0 and not self.allow_empty_first_page:
       ^^^^^^^^^^
  File "/opt/miniconda3/envs/website/lib/python3.11/site-packages/django/utils/functional.py", line 57, in __get__
    res = instance.__dict__[self.name] = self.func(instance)
                                         ^^^^^^^^^^^^^^^^^^^
  File "/opt/miniconda3/envs/website/lib/python3.11/site-packages/django/core/paginator.py", line 96, in count
    return c()
           ^^^
  File "/opt/miniconda3/envs/website/lib/python3.11/site-packages/django/db/models/query.py", line 621, in count
    return self.query.get_count(using=self.db)
           ^^^^^^^^^^^^^^^^^^^^^^^^^^^^^^^^^^^
  File "/opt/miniconda3/envs/website/lib/python3.11/site-packages/django/db/models/sql/query.py", line 559, in get_count
    return obj.get_aggregation(using, ["__count"])["__count"]
           ^^^^^^^^^^^^^^^^^^^^^^^^^^^^^^^^^^^^^^^
  File "/opt/miniconda3/envs/website/lib/python3.11/site-packages/django/db/models/sql/query.py", line 544, in get_aggregation
    result = compiler.execute_sql(SINGLE)
             ^^^^^^^^^^^^^^^^^^^^^^^^^^^^
  File "/opt/miniconda3/envs/website/lib/python3.11/site-packages/django/db/models/sql/compiler.py", line 1393, in execute_sql
    cursor = self.connection.cursor()
             ^^^^^^^^^^^^^^^^^^^^^^^^
  File "/opt/miniconda3/envs/website/lib/python3.11/site-packages/django/utils/asyncio.py", line 26, in inner
    return func(*args, **kwargs)
           ^^^^^^^^^^^^^^^^^^^^^
  File "/opt/miniconda3/envs/website/lib/python3.11/site-packages/django/db/backends/base/base.py", line 323, in cursor
    return self._cursor()
           ^^^^^^^^^^^^^^
  File "/opt/miniconda3/envs/website/lib/python3.11/site-packages/django/db/backends/base/base.py", line 299, in _cursor
    self.ensure_connection()
  File "/opt/miniconda3/envs/website/lib/python3.11/site-packages/django/utils/asyncio.py", line 26, in inner
    return func(*args, **kwargs)
           ^^^^^^^^^^^^^^^^^^^^^
  File "/opt/miniconda3/envs/website/lib/python3.11/site-packages/django/db/backends/base/base.py", line 281, in ensure_connection
    with self.wrap_database_errors:
  File "/opt/miniconda3/envs/website/lib/python3.11/site-packages/django/db/utils.py", line 91, in __exit__
    raise dj_exc_value.with_traceback(traceback) from exc_value
  File "/opt/miniconda3/envs/website/lib/python3.11/site-packages/django/db/backends/base/base.py", line 282, in ensure_connection
    self.connect()
  File "/opt/miniconda3/envs/website/lib/python3.11/site-packages/django/utils/asyncio.py", line 26, in inner
    return func(*args, **kwargs)
           ^^^^^^^^^^^^^^^^^^^^^
  File "/opt/miniconda3/envs/website/lib/python3.11/site-packages/django/db/backends/base/base.py", line 263, in connect
    self.connection = self.get_new_connection(conn_params)
                      ^^^^^^^^^^^^^^^^^^^^^^^^^^^^^^^^^^^^
  File "/opt/miniconda3/envs/website/lib/python3.11/site-packages/django/utils/asyncio.py", line 26, in inner
    return func(*args, **kwargs)
           ^^^^^^^^^^^^^^^^^^^^^
  File "/opt/miniconda3/envs/website/lib/python3.11/site-packages/django/db/backends/mysql/base.py", line 247, in get_new_connection
    connection = Database.connect(**conn_params)
                 ^^^^^^^^^^^^^^^^^^^^^^^^^^^^^^^
  File "/opt/miniconda3/envs/website/lib/python3.11/site-packages/pymysql/connections.py", line 361, in __init__
    self.connect()
  File "/opt/miniconda3/envs/website/lib/python3.11/site-packages/pymysql/connections.py", line 669, in connect
    self._request_authentication()
  File "/opt/miniconda3/envs/website/lib/python3.11/site-packages/pymysql/connections.py", line 957, in _request_authentication
    auth_packet = self._read_packet()
                  ^^^^^^^^^^^^^^^^^^^
  File "/opt/miniconda3/envs/website/lib/python3.11/site-packages/pymysql/connections.py", line 775, in _read_packet
    packet.raise_for_error()
  File "/opt/miniconda3/envs/website/lib/python3.11/site-packages/pymysql/protocol.py", line 219, in raise_for_error
    err.raise_mysql_exception(self._data)
  File "/opt/miniconda3/envs/website/lib/python3.11/site-packages/pymysql/err.py", line 150, in raise_mysql_exception
    raise errorclass(errno, errval)
django.db.utils.OperationalError: (1698, "Access denied for user 'root'@'localhost'")
Internal Server Error: /forum/course_resources/
Traceback (most recent call last):
  File "/opt/miniconda3/envs/website/lib/python3.11/site-packages/django/db/backends/base/base.py", line 282, in ensure_connection
    self.connect()
  File "/opt/miniconda3/envs/website/lib/python3.11/site-packages/django/utils/asyncio.py", line 26, in inner
    return func(*args, **kwargs)
           ^^^^^^^^^^^^^^^^^^^^^
  File "/opt/miniconda3/envs/website/lib/python3.11/site-packages/django/db/backends/base/base.py", line 263, in connect
    self.connection = self.get_new_connection(conn_params)
                      ^^^^^^^^^^^^^^^^^^^^^^^^^^^^^^^^^^^^
  File "/opt/miniconda3/envs/website/lib/python3.11/site-packages/django/utils/asyncio.py", line 26, in inner
    return func(*args, **kwargs)
           ^^^^^^^^^^^^^^^^^^^^^
  File "/opt/miniconda3/envs/website/lib/python3.11/site-packages/django/db/backends/mysql/base.py", line 247, in get_new_connection
    connection = Database.connect(**conn_params)
                 ^^^^^^^^^^^^^^^^^^^^^^^^^^^^^^^
  File "/opt/miniconda3/envs/website/lib/python3.11/site-packages/pymysql/connections.py", line 361, in __init__
    self.connect()
  File "/opt/miniconda3/envs/website/lib/python3.11/site-packages/pymysql/connections.py", line 669, in connect
    self._request_authentication()
  File "/opt/miniconda3/envs/website/lib/python3.11/site-packages/pymysql/connections.py", line 957, in _request_authentication
    auth_packet = self._read_packet()
                  ^^^^^^^^^^^^^^^^^^^
  File "/opt/miniconda3/envs/website/lib/python3.11/site-packages/pymysql/connections.py", line 775, in _read_packet
    packet.raise_for_error()
  File "/opt/miniconda3/envs/website/lib/python3.11/site-packages/pymysql/protocol.py", line 219, in raise_for_error
    err.raise_mysql_exception(self._data)
  File "/opt/miniconda3/envs/website/lib/python3.11/site-packages/pymysql/err.py", line 150, in raise_mysql_exception
    raise errorclass(errno, errval)
pymysql.err.OperationalError: (1698, "Access denied for user 'root'@'localhost'")

The above exception was the direct cause of the following exception:

Traceback (most recent call last):
  File "/opt/miniconda3/envs/website/lib/python3.11/site-packages/django/core/handlers/exception.py", line 55, in inner
    response = get_response(request)
               ^^^^^^^^^^^^^^^^^^^^^
  File "/opt/miniconda3/envs/website/lib/python3.11/site-packages/django/core/handlers/base.py", line 197, in _get_response
    response = wrapped_callback(request, *callback_args, **callback_kwargs)
               ^^^^^^^^^^^^^^^^^^^^^^^^^^^^^^^^^^^^^^^^^^^^^^^^^^^^^^^^^^^^
  File "/home/scs22/iGEM-2024-Coders/USTC-Software/Apps/forum/views.py", line 106, in course_resources_index
    page_obj = paginator.get_page(page_number)
               ^^^^^^^^^^^^^^^^^^^^^^^^^^^^^^^
  File "/opt/miniconda3/envs/website/lib/python3.11/site-packages/django/core/paginator.py", line 66, in get_page
    number = self.validate_number(number)
             ^^^^^^^^^^^^^^^^^^^^^^^^^^^^
  File "/opt/miniconda3/envs/website/lib/python3.11/site-packages/django/core/paginator.py", line 53, in validate_number
    if number > self.num_pages:
                ^^^^^^^^^^^^^^
  File "/opt/miniconda3/envs/website/lib/python3.11/site-packages/django/utils/functional.py", line 57, in __get__
    res = instance.__dict__[self.name] = self.func(instance)
                                         ^^^^^^^^^^^^^^^^^^^
  File "/opt/miniconda3/envs/website/lib/python3.11/site-packages/django/core/paginator.py", line 102, in num_pages
    if self.count == 0 and not self.allow_empty_first_page:
       ^^^^^^^^^^
  File "/opt/miniconda3/envs/website/lib/python3.11/site-packages/django/utils/functional.py", line 57, in __get__
    res = instance.__dict__[self.name] = self.func(instance)
                                         ^^^^^^^^^^^^^^^^^^^
  File "/opt/miniconda3/envs/website/lib/python3.11/site-packages/django/core/paginator.py", line 96, in count
    return c()
           ^^^
  File "/opt/miniconda3/envs/website/lib/python3.11/site-packages/django/db/models/query.py", line 621, in count
    return self.query.get_count(using=self.db)
           ^^^^^^^^^^^^^^^^^^^^^^^^^^^^^^^^^^^
  File "/opt/miniconda3/envs/website/lib/python3.11/site-packages/django/db/models/sql/query.py", line 559, in get_count
    return obj.get_aggregation(using, ["__count"])["__count"]
           ^^^^^^^^^^^^^^^^^^^^^^^^^^^^^^^^^^^^^^^
  File "/opt/miniconda3/envs/website/lib/python3.11/site-packages/django/db/models/sql/query.py", line 544, in get_aggregation
    result = compiler.execute_sql(SINGLE)
             ^^^^^^^^^^^^^^^^^^^^^^^^^^^^
  File "/opt/miniconda3/envs/website/lib/python3.11/site-packages/django/db/models/sql/compiler.py", line 1393, in execute_sql
    cursor = self.connection.cursor()
             ^^^^^^^^^^^^^^^^^^^^^^^^
  File "/opt/miniconda3/envs/website/lib/python3.11/site-packages/django/utils/asyncio.py", line 26, in inner
    return func(*args, **kwargs)
           ^^^^^^^^^^^^^^^^^^^^^
  File "/opt/miniconda3/envs/website/lib/python3.11/site-packages/django/db/backends/base/base.py", line 323, in cursor
    return self._cursor()
           ^^^^^^^^^^^^^^
  File "/opt/miniconda3/envs/website/lib/python3.11/site-packages/django/db/backends/base/base.py", line 299, in _cursor
    self.ensure_connection()
  File "/opt/miniconda3/envs/website/lib/python3.11/site-packages/django/utils/asyncio.py", line 26, in inner
    return func(*args, **kwargs)
           ^^^^^^^^^^^^^^^^^^^^^
  File "/opt/miniconda3/envs/website/lib/python3.11/site-packages/django/db/backends/base/base.py", line 281, in ensure_connection
    with self.wrap_database_errors:
  File "/opt/miniconda3/envs/website/lib/python3.11/site-packages/django/db/utils.py", line 91, in __exit__
    raise dj_exc_value.with_traceback(traceback) from exc_value
  File "/opt/miniconda3/envs/website/lib/python3.11/site-packages/django/db/backends/base/base.py", line 282, in ensure_connection
    self.connect()
  File "/opt/miniconda3/envs/website/lib/python3.11/site-packages/django/utils/asyncio.py", line 26, in inner
    return func(*args, **kwargs)
           ^^^^^^^^^^^^^^^^^^^^^
  File "/opt/miniconda3/envs/website/lib/python3.11/site-packages/django/db/backends/base/base.py", line 263, in connect
    self.connection = self.get_new_connection(conn_params)
                      ^^^^^^^^^^^^^^^^^^^^^^^^^^^^^^^^^^^^
  File "/opt/miniconda3/envs/website/lib/python3.11/site-packages/django/utils/asyncio.py", line 26, in inner
    return func(*args, **kwargs)
           ^^^^^^^^^^^^^^^^^^^^^
  File "/opt/miniconda3/envs/website/lib/python3.11/site-packages/django/db/backends/mysql/base.py", line 247, in get_new_connection
    connection = Database.connect(**conn_params)
                 ^^^^^^^^^^^^^^^^^^^^^^^^^^^^^^^
  File "/opt/miniconda3/envs/website/lib/python3.11/site-packages/pymysql/connections.py", line 361, in __init__
    self.connect()
  File "/opt/miniconda3/envs/website/lib/python3.11/site-packages/pymysql/connections.py", line 669, in connect
    self._request_authentication()
  File "/opt/miniconda3/envs/website/lib/python3.11/site-packages/pymysql/connections.py", line 957, in _request_authentication
    auth_packet = self._read_packet()
                  ^^^^^^^^^^^^^^^^^^^
  File "/opt/miniconda3/envs/website/lib/python3.11/site-packages/pymysql/connections.py", line 775, in _read_packet
    packet.raise_for_error()
  File "/opt/miniconda3/envs/website/lib/python3.11/site-packages/pymysql/protocol.py", line 219, in raise_for_error
    err.raise_mysql_exception(self._data)
  File "/opt/miniconda3/envs/website/lib/python3.11/site-packages/pymysql/err.py", line 150, in raise_mysql_exception
    raise errorclass(errno, errval)
django.db.utils.OperationalError: (1698, "Access denied for user 'root'@'localhost'")
Internal Server Error: /forum/course_resources/
Traceback (most recent call last):
  File "/opt/miniconda3/envs/website/lib/python3.11/site-packages/django/db/backends/base/base.py", line 282, in ensure_connection
    self.connect()
  File "/opt/miniconda3/envs/website/lib/python3.11/site-packages/django/utils/asyncio.py", line 26, in inner
    return func(*args, **kwargs)
           ^^^^^^^^^^^^^^^^^^^^^
  File "/opt/miniconda3/envs/website/lib/python3.11/site-packages/django/db/backends/base/base.py", line 263, in connect
    self.connection = self.get_new_connection(conn_params)
                      ^^^^^^^^^^^^^^^^^^^^^^^^^^^^^^^^^^^^
  File "/opt/miniconda3/envs/website/lib/python3.11/site-packages/django/utils/asyncio.py", line 26, in inner
    return func(*args, **kwargs)
           ^^^^^^^^^^^^^^^^^^^^^
  File "/opt/miniconda3/envs/website/lib/python3.11/site-packages/django/db/backends/mysql/base.py", line 247, in get_new_connection
    connection = Database.connect(**conn_params)
                 ^^^^^^^^^^^^^^^^^^^^^^^^^^^^^^^
  File "/opt/miniconda3/envs/website/lib/python3.11/site-packages/pymysql/connections.py", line 361, in __init__
    self.connect()
  File "/opt/miniconda3/envs/website/lib/python3.11/site-packages/pymysql/connections.py", line 669, in connect
    self._request_authentication()
  File "/opt/miniconda3/envs/website/lib/python3.11/site-packages/pymysql/connections.py", line 957, in _request_authentication
    auth_packet = self._read_packet()
                  ^^^^^^^^^^^^^^^^^^^
  File "/opt/miniconda3/envs/website/lib/python3.11/site-packages/pymysql/connections.py", line 775, in _read_packet
    packet.raise_for_error()
  File "/opt/miniconda3/envs/website/lib/python3.11/site-packages/pymysql/protocol.py", line 219, in raise_for_error
    err.raise_mysql_exception(self._data)
  File "/opt/miniconda3/envs/website/lib/python3.11/site-packages/pymysql/err.py", line 150, in raise_mysql_exception
    raise errorclass(errno, errval)
pymysql.err.OperationalError: (1698, "Access denied for user 'root'@'localhost'")

The above exception was the direct cause of the following exception:

Traceback (most recent call last):
  File "/opt/miniconda3/envs/website/lib/python3.11/site-packages/django/core/handlers/exception.py", line 55, in inner
    response = get_response(request)
               ^^^^^^^^^^^^^^^^^^^^^
  File "/opt/miniconda3/envs/website/lib/python3.11/site-packages/django/core/handlers/base.py", line 197, in _get_response
    response = wrapped_callback(request, *callback_args, **callback_kwargs)
               ^^^^^^^^^^^^^^^^^^^^^^^^^^^^^^^^^^^^^^^^^^^^^^^^^^^^^^^^^^^^
  File "/home/scs22/iGEM-2024-Coders/USTC-Software/Apps/forum/views.py", line 106, in course_resources_index
    page_obj = paginator.get_page(page_number)
               ^^^^^^^^^^^^^^^^^^^^^^^^^^^^^^^
  File "/opt/miniconda3/envs/website/lib/python3.11/site-packages/django/core/paginator.py", line 66, in get_page
    number = self.validate_number(number)
             ^^^^^^^^^^^^^^^^^^^^^^^^^^^^
  File "/opt/miniconda3/envs/website/lib/python3.11/site-packages/django/core/paginator.py", line 53, in validate_number
    if number > self.num_pages:
                ^^^^^^^^^^^^^^
  File "/opt/miniconda3/envs/website/lib/python3.11/site-packages/django/utils/functional.py", line 57, in __get__
    res = instance.__dict__[self.name] = self.func(instance)
                                         ^^^^^^^^^^^^^^^^^^^
  File "/opt/miniconda3/envs/website/lib/python3.11/site-packages/django/core/paginator.py", line 102, in num_pages
    if self.count == 0 and not self.allow_empty_first_page:
       ^^^^^^^^^^
  File "/opt/miniconda3/envs/website/lib/python3.11/site-packages/django/utils/functional.py", line 57, in __get__
    res = instance.__dict__[self.name] = self.func(instance)
                                         ^^^^^^^^^^^^^^^^^^^
  File "/opt/miniconda3/envs/website/lib/python3.11/site-packages/django/core/paginator.py", line 96, in count
    return c()
           ^^^
  File "/opt/miniconda3/envs/website/lib/python3.11/site-packages/django/db/models/query.py", line 621, in count
    return self.query.get_count(using=self.db)
           ^^^^^^^^^^^^^^^^^^^^^^^^^^^^^^^^^^^
  File "/opt/miniconda3/envs/website/lib/python3.11/site-packages/django/db/models/sql/query.py", line 559, in get_count
    return obj.get_aggregation(using, ["__count"])["__count"]
           ^^^^^^^^^^^^^^^^^^^^^^^^^^^^^^^^^^^^^^^
  File "/opt/miniconda3/envs/website/lib/python3.11/site-packages/django/db/models/sql/query.py", line 544, in get_aggregation
    result = compiler.execute_sql(SINGLE)
             ^^^^^^^^^^^^^^^^^^^^^^^^^^^^
  File "/opt/miniconda3/envs/website/lib/python3.11/site-packages/django/db/models/sql/compiler.py", line 1393, in execute_sql
    cursor = self.connection.cursor()
             ^^^^^^^^^^^^^^^^^^^^^^^^
  File "/opt/miniconda3/envs/website/lib/python3.11/site-packages/django/utils/asyncio.py", line 26, in inner
    return func(*args, **kwargs)
           ^^^^^^^^^^^^^^^^^^^^^
  File "/opt/miniconda3/envs/website/lib/python3.11/site-packages/django/db/backends/base/base.py", line 323, in cursor
    return self._cursor()
           ^^^^^^^^^^^^^^
  File "/opt/miniconda3/envs/website/lib/python3.11/site-packages/django/db/backends/base/base.py", line 299, in _cursor
    self.ensure_connection()
  File "/opt/miniconda3/envs/website/lib/python3.11/site-packages/django/utils/asyncio.py", line 26, in inner
    return func(*args, **kwargs)
           ^^^^^^^^^^^^^^^^^^^^^
  File "/opt/miniconda3/envs/website/lib/python3.11/site-packages/django/db/backends/base/base.py", line 281, in ensure_connection
    with self.wrap_database_errors:
  File "/opt/miniconda3/envs/website/lib/python3.11/site-packages/django/db/utils.py", line 91, in __exit__
    raise dj_exc_value.with_traceback(traceback) from exc_value
  File "/opt/miniconda3/envs/website/lib/python3.11/site-packages/django/db/backends/base/base.py", line 282, in ensure_connection
    self.connect()
  File "/opt/miniconda3/envs/website/lib/python3.11/site-packages/django/utils/asyncio.py", line 26, in inner
    return func(*args, **kwargs)
           ^^^^^^^^^^^^^^^^^^^^^
  File "/opt/miniconda3/envs/website/lib/python3.11/site-packages/django/db/backends/base/base.py", line 263, in connect
    self.connection = self.get_new_connection(conn_params)
                      ^^^^^^^^^^^^^^^^^^^^^^^^^^^^^^^^^^^^
  File "/opt/miniconda3/envs/website/lib/python3.11/site-packages/django/utils/asyncio.py", line 26, in inner
    return func(*args, **kwargs)
           ^^^^^^^^^^^^^^^^^^^^^
  File "/opt/miniconda3/envs/website/lib/python3.11/site-packages/django/db/backends/mysql/base.py", line 247, in get_new_connection
    connection = Database.connect(**conn_params)
                 ^^^^^^^^^^^^^^^^^^^^^^^^^^^^^^^
  File "/opt/miniconda3/envs/website/lib/python3.11/site-packages/pymysql/connections.py", line 361, in __init__
    self.connect()
  File "/opt/miniconda3/envs/website/lib/python3.11/site-packages/pymysql/connections.py", line 669, in connect
    self._request_authentication()
  File "/opt/miniconda3/envs/website/lib/python3.11/site-packages/pymysql/connections.py", line 957, in _request_authentication
    auth_packet = self._read_packet()
                  ^^^^^^^^^^^^^^^^^^^
  File "/opt/miniconda3/envs/website/lib/python3.11/site-packages/pymysql/connections.py", line 775, in _read_packet
    packet.raise_for_error()
  File "/opt/miniconda3/envs/website/lib/python3.11/site-packages/pymysql/protocol.py", line 219, in raise_for_error
    err.raise_mysql_exception(self._data)
  File "/opt/miniconda3/envs/website/lib/python3.11/site-packages/pymysql/err.py", line 150, in raise_mysql_exception
    raise errorclass(errno, errval)
django.db.utils.OperationalError: (1698, "Access denied for user 'root'@'localhost'")
Internal Server Error: /forum/course_resources/
Traceback (most recent call last):
  File "/opt/miniconda3/envs/website/lib/python3.11/site-packages/django/db/backends/base/base.py", line 282, in ensure_connection
    self.connect()
  File "/opt/miniconda3/envs/website/lib/python3.11/site-packages/django/utils/asyncio.py", line 26, in inner
    return func(*args, **kwargs)
           ^^^^^^^^^^^^^^^^^^^^^
  File "/opt/miniconda3/envs/website/lib/python3.11/site-packages/django/db/backends/base/base.py", line 263, in connect
    self.connection = self.get_new_connection(conn_params)
                      ^^^^^^^^^^^^^^^^^^^^^^^^^^^^^^^^^^^^
  File "/opt/miniconda3/envs/website/lib/python3.11/site-packages/django/utils/asyncio.py", line 26, in inner
    return func(*args, **kwargs)
           ^^^^^^^^^^^^^^^^^^^^^
  File "/opt/miniconda3/envs/website/lib/python3.11/site-packages/django/db/backends/mysql/base.py", line 247, in get_new_connection
    connection = Database.connect(**conn_params)
                 ^^^^^^^^^^^^^^^^^^^^^^^^^^^^^^^
  File "/opt/miniconda3/envs/website/lib/python3.11/site-packages/pymysql/connections.py", line 361, in __init__
    self.connect()
  File "/opt/miniconda3/envs/website/lib/python3.11/site-packages/pymysql/connections.py", line 669, in connect
    self._request_authentication()
  File "/opt/miniconda3/envs/website/lib/python3.11/site-packages/pymysql/connections.py", line 957, in _request_authentication
    auth_packet = self._read_packet()
                  ^^^^^^^^^^^^^^^^^^^
  File "/opt/miniconda3/envs/website/lib/python3.11/site-packages/pymysql/connections.py", line 775, in _read_packet
    packet.raise_for_error()
  File "/opt/miniconda3/envs/website/lib/python3.11/site-packages/pymysql/protocol.py", line 219, in raise_for_error
    err.raise_mysql_exception(self._data)
  File "/opt/miniconda3/envs/website/lib/python3.11/site-packages/pymysql/err.py", line 150, in raise_mysql_exception
    raise errorclass(errno, errval)
pymysql.err.OperationalError: (1698, "Access denied for user 'root'@'localhost'")

The above exception was the direct cause of the following exception:

Traceback (most recent call last):
  File "/opt/miniconda3/envs/website/lib/python3.11/site-packages/django/core/handlers/exception.py", line 55, in inner
    response = get_response(request)
               ^^^^^^^^^^^^^^^^^^^^^
  File "/opt/miniconda3/envs/website/lib/python3.11/site-packages/django/core/handlers/base.py", line 197, in _get_response
    response = wrapped_callback(request, *callback_args, **callback_kwargs)
               ^^^^^^^^^^^^^^^^^^^^^^^^^^^^^^^^^^^^^^^^^^^^^^^^^^^^^^^^^^^^
  File "/home/scs22/iGEM-2024-Coders/USTC-Software/Apps/forum/views.py", line 106, in course_resources_index
    page_obj = paginator.get_page(page_number)
               ^^^^^^^^^^^^^^^^^^^^^^^^^^^^^^^
  File "/opt/miniconda3/envs/website/lib/python3.11/site-packages/django/core/paginator.py", line 66, in get_page
    number = self.validate_number(number)
             ^^^^^^^^^^^^^^^^^^^^^^^^^^^^
  File "/opt/miniconda3/envs/website/lib/python3.11/site-packages/django/core/paginator.py", line 53, in validate_number
    if number > self.num_pages:
                ^^^^^^^^^^^^^^
  File "/opt/miniconda3/envs/website/lib/python3.11/site-packages/django/utils/functional.py", line 57, in __get__
    res = instance.__dict__[self.name] = self.func(instance)
                                         ^^^^^^^^^^^^^^^^^^^
  File "/opt/miniconda3/envs/website/lib/python3.11/site-packages/django/core/paginator.py", line 102, in num_pages
    if self.count == 0 and not self.allow_empty_first_page:
       ^^^^^^^^^^
  File "/opt/miniconda3/envs/website/lib/python3.11/site-packages/django/utils/functional.py", line 57, in __get__
    res = instance.__dict__[self.name] = self.func(instance)
                                         ^^^^^^^^^^^^^^^^^^^
  File "/opt/miniconda3/envs/website/lib/python3.11/site-packages/django/core/paginator.py", line 96, in count
    return c()
           ^^^
  File "/opt/miniconda3/envs/website/lib/python3.11/site-packages/django/db/models/query.py", line 621, in count
    return self.query.get_count(using=self.db)
           ^^^^^^^^^^^^^^^^^^^^^^^^^^^^^^^^^^^
  File "/opt/miniconda3/envs/website/lib/python3.11/site-packages/django/db/models/sql/query.py", line 559, in get_count
    return obj.get_aggregation(using, ["__count"])["__count"]
           ^^^^^^^^^^^^^^^^^^^^^^^^^^^^^^^^^^^^^^^
  File "/opt/miniconda3/envs/website/lib/python3.11/site-packages/django/db/models/sql/query.py", line 544, in get_aggregation
    result = compiler.execute_sql(SINGLE)
             ^^^^^^^^^^^^^^^^^^^^^^^^^^^^
  File "/opt/miniconda3/envs/website/lib/python3.11/site-packages/django/db/models/sql/compiler.py", line 1393, in execute_sql
    cursor = self.connection.cursor()
             ^^^^^^^^^^^^^^^^^^^^^^^^
  File "/opt/miniconda3/envs/website/lib/python3.11/site-packages/django/utils/asyncio.py", line 26, in inner
    return func(*args, **kwargs)
           ^^^^^^^^^^^^^^^^^^^^^
  File "/opt/miniconda3/envs/website/lib/python3.11/site-packages/django/db/backends/base/base.py", line 323, in cursor
    return self._cursor()
           ^^^^^^^^^^^^^^
  File "/opt/miniconda3/envs/website/lib/python3.11/site-packages/django/db/backends/base/base.py", line 299, in _cursor
    self.ensure_connection()
  File "/opt/miniconda3/envs/website/lib/python3.11/site-packages/django/utils/asyncio.py", line 26, in inner
    return func(*args, **kwargs)
           ^^^^^^^^^^^^^^^^^^^^^
  File "/opt/miniconda3/envs/website/lib/python3.11/site-packages/django/db/backends/base/base.py", line 281, in ensure_connection
    with self.wrap_database_errors:
  File "/opt/miniconda3/envs/website/lib/python3.11/site-packages/django/db/utils.py", line 91, in __exit__
    raise dj_exc_value.with_traceback(traceback) from exc_value
  File "/opt/miniconda3/envs/website/lib/python3.11/site-packages/django/db/backends/base/base.py", line 282, in ensure_connection
    self.connect()
  File "/opt/miniconda3/envs/website/lib/python3.11/site-packages/django/utils/asyncio.py", line 26, in inner
    return func(*args, **kwargs)
           ^^^^^^^^^^^^^^^^^^^^^
  File "/opt/miniconda3/envs/website/lib/python3.11/site-packages/django/db/backends/base/base.py", line 263, in connect
    self.connection = self.get_new_connection(conn_params)
                      ^^^^^^^^^^^^^^^^^^^^^^^^^^^^^^^^^^^^
  File "/opt/miniconda3/envs/website/lib/python3.11/site-packages/django/utils/asyncio.py", line 26, in inner
    return func(*args, **kwargs)
           ^^^^^^^^^^^^^^^^^^^^^
  File "/opt/miniconda3/envs/website/lib/python3.11/site-packages/django/db/backends/mysql/base.py", line 247, in get_new_connection
    connection = Database.connect(**conn_params)
                 ^^^^^^^^^^^^^^^^^^^^^^^^^^^^^^^
  File "/opt/miniconda3/envs/website/lib/python3.11/site-packages/pymysql/connections.py", line 361, in __init__
    self.connect()
  File "/opt/miniconda3/envs/website/lib/python3.11/site-packages/pymysql/connections.py", line 669, in connect
    self._request_authentication()
  File "/opt/miniconda3/envs/website/lib/python3.11/site-packages/pymysql/connections.py", line 957, in _request_authentication
    auth_packet = self._read_packet()
                  ^^^^^^^^^^^^^^^^^^^
  File "/opt/miniconda3/envs/website/lib/python3.11/site-packages/pymysql/connections.py", line 775, in _read_packet
    packet.raise_for_error()
  File "/opt/miniconda3/envs/website/lib/python3.11/site-packages/pymysql/protocol.py", line 219, in raise_for_error
    err.raise_mysql_exception(self._data)
  File "/opt/miniconda3/envs/website/lib/python3.11/site-packages/pymysql/err.py", line 150, in raise_mysql_exception
    raise errorclass(errno, errval)
django.db.utils.OperationalError: (1698, "Access denied for user 'root'@'localhost'")
Internal Server Error: /forum/course_resources/
Traceback (most recent call last):
  File "/opt/miniconda3/envs/website/lib/python3.11/site-packages/django/db/backends/base/base.py", line 282, in ensure_connection
    self.connect()
  File "/opt/miniconda3/envs/website/lib/python3.11/site-packages/django/utils/asyncio.py", line 26, in inner
    return func(*args, **kwargs)
           ^^^^^^^^^^^^^^^^^^^^^
  File "/opt/miniconda3/envs/website/lib/python3.11/site-packages/django/db/backends/base/base.py", line 263, in connect
    self.connection = self.get_new_connection(conn_params)
                      ^^^^^^^^^^^^^^^^^^^^^^^^^^^^^^^^^^^^
  File "/opt/miniconda3/envs/website/lib/python3.11/site-packages/django/utils/asyncio.py", line 26, in inner
    return func(*args, **kwargs)
           ^^^^^^^^^^^^^^^^^^^^^
  File "/opt/miniconda3/envs/website/lib/python3.11/site-packages/django/db/backends/mysql/base.py", line 247, in get_new_connection
    connection = Database.connect(**conn_params)
                 ^^^^^^^^^^^^^^^^^^^^^^^^^^^^^^^
  File "/opt/miniconda3/envs/website/lib/python3.11/site-packages/pymysql/connections.py", line 361, in __init__
    self.connect()
  File "/opt/miniconda3/envs/website/lib/python3.11/site-packages/pymysql/connections.py", line 669, in connect
    self._request_authentication()
  File "/opt/miniconda3/envs/website/lib/python3.11/site-packages/pymysql/connections.py", line 957, in _request_authentication
    auth_packet = self._read_packet()
                  ^^^^^^^^^^^^^^^^^^^
  File "/opt/miniconda3/envs/website/lib/python3.11/site-packages/pymysql/connections.py", line 775, in _read_packet
    packet.raise_for_error()
  File "/opt/miniconda3/envs/website/lib/python3.11/site-packages/pymysql/protocol.py", line 219, in raise_for_error
    err.raise_mysql_exception(self._data)
  File "/opt/miniconda3/envs/website/lib/python3.11/site-packages/pymysql/err.py", line 150, in raise_mysql_exception
    raise errorclass(errno, errval)
pymysql.err.OperationalError: (1698, "Access denied for user 'root'@'localhost'")

The above exception was the direct cause of the following exception:

Traceback (most recent call last):
  File "/opt/miniconda3/envs/website/lib/python3.11/site-packages/django/core/handlers/exception.py", line 55, in inner
    response = get_response(request)
               ^^^^^^^^^^^^^^^^^^^^^
  File "/opt/miniconda3/envs/website/lib/python3.11/site-packages/django/core/handlers/base.py", line 197, in _get_response
    response = wrapped_callback(request, *callback_args, **callback_kwargs)
               ^^^^^^^^^^^^^^^^^^^^^^^^^^^^^^^^^^^^^^^^^^^^^^^^^^^^^^^^^^^^
  File "/home/scs22/iGEM-2024-Coders/USTC-Software/Apps/forum/views.py", line 106, in course_resources_index
    page_obj = paginator.get_page(page_number)
               ^^^^^^^^^^^^^^^^^^^^^^^^^^^^^^^
  File "/opt/miniconda3/envs/website/lib/python3.11/site-packages/django/core/paginator.py", line 66, in get_page
    number = self.validate_number(number)
             ^^^^^^^^^^^^^^^^^^^^^^^^^^^^
  File "/opt/miniconda3/envs/website/lib/python3.11/site-packages/django/core/paginator.py", line 53, in validate_number
    if number > self.num_pages:
                ^^^^^^^^^^^^^^
  File "/opt/miniconda3/envs/website/lib/python3.11/site-packages/django/utils/functional.py", line 57, in __get__
    res = instance.__dict__[self.name] = self.func(instance)
                                         ^^^^^^^^^^^^^^^^^^^
  File "/opt/miniconda3/envs/website/lib/python3.11/site-packages/django/core/paginator.py", line 102, in num_pages
    if self.count == 0 and not self.allow_empty_first_page:
       ^^^^^^^^^^
  File "/opt/miniconda3/envs/website/lib/python3.11/site-packages/django/utils/functional.py", line 57, in __get__
    res = instance.__dict__[self.name] = self.func(instance)
                                         ^^^^^^^^^^^^^^^^^^^
  File "/opt/miniconda3/envs/website/lib/python3.11/site-packages/django/core/paginator.py", line 96, in count
    return c()
           ^^^
  File "/opt/miniconda3/envs/website/lib/python3.11/site-packages/django/db/models/query.py", line 621, in count
    return self.query.get_count(using=self.db)
           ^^^^^^^^^^^^^^^^^^^^^^^^^^^^^^^^^^^
  File "/opt/miniconda3/envs/website/lib/python3.11/site-packages/django/db/models/sql/query.py", line 559, in get_count
    return obj.get_aggregation(using, ["__count"])["__count"]
           ^^^^^^^^^^^^^^^^^^^^^^^^^^^^^^^^^^^^^^^
  File "/opt/miniconda3/envs/website/lib/python3.11/site-packages/django/db/models/sql/query.py", line 544, in get_aggregation
    result = compiler.execute_sql(SINGLE)
             ^^^^^^^^^^^^^^^^^^^^^^^^^^^^
  File "/opt/miniconda3/envs/website/lib/python3.11/site-packages/django/db/models/sql/compiler.py", line 1393, in execute_sql
    cursor = self.connection.cursor()
             ^^^^^^^^^^^^^^^^^^^^^^^^
  File "/opt/miniconda3/envs/website/lib/python3.11/site-packages/django/utils/asyncio.py", line 26, in inner
    return func(*args, **kwargs)
           ^^^^^^^^^^^^^^^^^^^^^
  File "/opt/miniconda3/envs/website/lib/python3.11/site-packages/django/db/backends/base/base.py", line 323, in cursor
    return self._cursor()
           ^^^^^^^^^^^^^^
  File "/opt/miniconda3/envs/website/lib/python3.11/site-packages/django/db/backends/base/base.py", line 299, in _cursor
    self.ensure_connection()
  File "/opt/miniconda3/envs/website/lib/python3.11/site-packages/django/utils/asyncio.py", line 26, in inner
    return func(*args, **kwargs)
           ^^^^^^^^^^^^^^^^^^^^^
  File "/opt/miniconda3/envs/website/lib/python3.11/site-packages/django/db/backends/base/base.py", line 281, in ensure_connection
    with self.wrap_database_errors:
  File "/opt/miniconda3/envs/website/lib/python3.11/site-packages/django/db/utils.py", line 91, in __exit__
    raise dj_exc_value.with_traceback(traceback) from exc_value
  File "/opt/miniconda3/envs/website/lib/python3.11/site-packages/django/db/backends/base/base.py", line 282, in ensure_connection
    self.connect()
  File "/opt/miniconda3/envs/website/lib/python3.11/site-packages/django/utils/asyncio.py", line 26, in inner
    return func(*args, **kwargs)
           ^^^^^^^^^^^^^^^^^^^^^
  File "/opt/miniconda3/envs/website/lib/python3.11/site-packages/django/db/backends/base/base.py", line 263, in connect
    self.connection = self.get_new_connection(conn_params)
                      ^^^^^^^^^^^^^^^^^^^^^^^^^^^^^^^^^^^^
  File "/opt/miniconda3/envs/website/lib/python3.11/site-packages/django/utils/asyncio.py", line 26, in inner
    return func(*args, **kwargs)
           ^^^^^^^^^^^^^^^^^^^^^
  File "/opt/miniconda3/envs/website/lib/python3.11/site-packages/django/db/backends/mysql/base.py", line 247, in get_new_connection
    connection = Database.connect(**conn_params)
                 ^^^^^^^^^^^^^^^^^^^^^^^^^^^^^^^
  File "/opt/miniconda3/envs/website/lib/python3.11/site-packages/pymysql/connections.py", line 361, in __init__
    self.connect()
  File "/opt/miniconda3/envs/website/lib/python3.11/site-packages/pymysql/connections.py", line 669, in connect
    self._request_authentication()
  File "/opt/miniconda3/envs/website/lib/python3.11/site-packages/pymysql/connections.py", line 957, in _request_authentication
    auth_packet = self._read_packet()
                  ^^^^^^^^^^^^^^^^^^^
  File "/opt/miniconda3/envs/website/lib/python3.11/site-packages/pymysql/connections.py", line 775, in _read_packet
    packet.raise_for_error()
  File "/opt/miniconda3/envs/website/lib/python3.11/site-packages/pymysql/protocol.py", line 219, in raise_for_error
    err.raise_mysql_exception(self._data)
  File "/opt/miniconda3/envs/website/lib/python3.11/site-packages/pymysql/err.py", line 150, in raise_mysql_exception
    raise errorclass(errno, errval)
django.db.utils.OperationalError: (1698, "Access denied for user 'root'@'localhost'")
Not Found: /shell
Internal Server Error: /forum/course_resources/
Traceback (most recent call last):
  File "/opt/miniconda3/envs/website/lib/python3.11/site-packages/django/db/backends/base/base.py", line 282, in ensure_connection
    self.connect()
  File "/opt/miniconda3/envs/website/lib/python3.11/site-packages/django/utils/asyncio.py", line 26, in inner
    return func(*args, **kwargs)
           ^^^^^^^^^^^^^^^^^^^^^
  File "/opt/miniconda3/envs/website/lib/python3.11/site-packages/django/db/backends/base/base.py", line 263, in connect
    self.connection = self.get_new_connection(conn_params)
                      ^^^^^^^^^^^^^^^^^^^^^^^^^^^^^^^^^^^^
  File "/opt/miniconda3/envs/website/lib/python3.11/site-packages/django/utils/asyncio.py", line 26, in inner
    return func(*args, **kwargs)
           ^^^^^^^^^^^^^^^^^^^^^
  File "/opt/miniconda3/envs/website/lib/python3.11/site-packages/django/db/backends/mysql/base.py", line 247, in get_new_connection
    connection = Database.connect(**conn_params)
                 ^^^^^^^^^^^^^^^^^^^^^^^^^^^^^^^
  File "/opt/miniconda3/envs/website/lib/python3.11/site-packages/pymysql/connections.py", line 361, in __init__
    self.connect()
  File "/opt/miniconda3/envs/website/lib/python3.11/site-packages/pymysql/connections.py", line 669, in connect
    self._request_authentication()
  File "/opt/miniconda3/envs/website/lib/python3.11/site-packages/pymysql/connections.py", line 957, in _request_authentication
    auth_packet = self._read_packet()
                  ^^^^^^^^^^^^^^^^^^^
  File "/opt/miniconda3/envs/website/lib/python3.11/site-packages/pymysql/connections.py", line 775, in _read_packet
    packet.raise_for_error()
  File "/opt/miniconda3/envs/website/lib/python3.11/site-packages/pymysql/protocol.py", line 219, in raise_for_error
    err.raise_mysql_exception(self._data)
  File "/opt/miniconda3/envs/website/lib/python3.11/site-packages/pymysql/err.py", line 150, in raise_mysql_exception
    raise errorclass(errno, errval)
pymysql.err.OperationalError: (1698, "Access denied for user 'root'@'localhost'")

The above exception was the direct cause of the following exception:

Traceback (most recent call last):
  File "/opt/miniconda3/envs/website/lib/python3.11/site-packages/django/core/handlers/exception.py", line 55, in inner
    response = get_response(request)
               ^^^^^^^^^^^^^^^^^^^^^
  File "/opt/miniconda3/envs/website/lib/python3.11/site-packages/django/core/handlers/base.py", line 197, in _get_response
    response = wrapped_callback(request, *callback_args, **callback_kwargs)
               ^^^^^^^^^^^^^^^^^^^^^^^^^^^^^^^^^^^^^^^^^^^^^^^^^^^^^^^^^^^^
  File "/home/scs22/iGEM-2024-Coders/USTC-Software/Apps/forum/views.py", line 106, in course_resources_index
    page_obj = paginator.get_page(page_number)
               ^^^^^^^^^^^^^^^^^^^^^^^^^^^^^^^
  File "/opt/miniconda3/envs/website/lib/python3.11/site-packages/django/core/paginator.py", line 66, in get_page
    number = self.validate_number(number)
             ^^^^^^^^^^^^^^^^^^^^^^^^^^^^
  File "/opt/miniconda3/envs/website/lib/python3.11/site-packages/django/core/paginator.py", line 53, in validate_number
    if number > self.num_pages:
                ^^^^^^^^^^^^^^
  File "/opt/miniconda3/envs/website/lib/python3.11/site-packages/django/utils/functional.py", line 57, in __get__
    res = instance.__dict__[self.name] = self.func(instance)
                                         ^^^^^^^^^^^^^^^^^^^
  File "/opt/miniconda3/envs/website/lib/python3.11/site-packages/django/core/paginator.py", line 102, in num_pages
    if self.count == 0 and not self.allow_empty_first_page:
       ^^^^^^^^^^
  File "/opt/miniconda3/envs/website/lib/python3.11/site-packages/django/utils/functional.py", line 57, in __get__
    res = instance.__dict__[self.name] = self.func(instance)
                                         ^^^^^^^^^^^^^^^^^^^
  File "/opt/miniconda3/envs/website/lib/python3.11/site-packages/django/core/paginator.py", line 96, in count
    return c()
           ^^^
  File "/opt/miniconda3/envs/website/lib/python3.11/site-packages/django/db/models/query.py", line 621, in count
    return self.query.get_count(using=self.db)
           ^^^^^^^^^^^^^^^^^^^^^^^^^^^^^^^^^^^
  File "/opt/miniconda3/envs/website/lib/python3.11/site-packages/django/db/models/sql/query.py", line 559, in get_count
    return obj.get_aggregation(using, ["__count"])["__count"]
           ^^^^^^^^^^^^^^^^^^^^^^^^^^^^^^^^^^^^^^^
  File "/opt/miniconda3/envs/website/lib/python3.11/site-packages/django/db/models/sql/query.py", line 544, in get_aggregation
    result = compiler.execute_sql(SINGLE)
             ^^^^^^^^^^^^^^^^^^^^^^^^^^^^
  File "/opt/miniconda3/envs/website/lib/python3.11/site-packages/django/db/models/sql/compiler.py", line 1393, in execute_sql
    cursor = self.connection.cursor()
             ^^^^^^^^^^^^^^^^^^^^^^^^
  File "/opt/miniconda3/envs/website/lib/python3.11/site-packages/django/utils/asyncio.py", line 26, in inner
    return func(*args, **kwargs)
           ^^^^^^^^^^^^^^^^^^^^^
  File "/opt/miniconda3/envs/website/lib/python3.11/site-packages/django/db/backends/base/base.py", line 323, in cursor
    return self._cursor()
           ^^^^^^^^^^^^^^
  File "/opt/miniconda3/envs/website/lib/python3.11/site-packages/django/db/backends/base/base.py", line 299, in _cursor
    self.ensure_connection()
  File "/opt/miniconda3/envs/website/lib/python3.11/site-packages/django/utils/asyncio.py", line 26, in inner
    return func(*args, **kwargs)
           ^^^^^^^^^^^^^^^^^^^^^
  File "/opt/miniconda3/envs/website/lib/python3.11/site-packages/django/db/backends/base/base.py", line 281, in ensure_connection
    with self.wrap_database_errors:
  File "/opt/miniconda3/envs/website/lib/python3.11/site-packages/django/db/utils.py", line 91, in __exit__
    raise dj_exc_value.with_traceback(traceback) from exc_value
  File "/opt/miniconda3/envs/website/lib/python3.11/site-packages/django/db/backends/base/base.py", line 282, in ensure_connection
    self.connect()
  File "/opt/miniconda3/envs/website/lib/python3.11/site-packages/django/utils/asyncio.py", line 26, in inner
    return func(*args, **kwargs)
           ^^^^^^^^^^^^^^^^^^^^^
  File "/opt/miniconda3/envs/website/lib/python3.11/site-packages/django/db/backends/base/base.py", line 263, in connect
    self.connection = self.get_new_connection(conn_params)
                      ^^^^^^^^^^^^^^^^^^^^^^^^^^^^^^^^^^^^
  File "/opt/miniconda3/envs/website/lib/python3.11/site-packages/django/utils/asyncio.py", line 26, in inner
    return func(*args, **kwargs)
           ^^^^^^^^^^^^^^^^^^^^^
  File "/opt/miniconda3/envs/website/lib/python3.11/site-packages/django/db/backends/mysql/base.py", line 247, in get_new_connection
    connection = Database.connect(**conn_params)
                 ^^^^^^^^^^^^^^^^^^^^^^^^^^^^^^^
  File "/opt/miniconda3/envs/website/lib/python3.11/site-packages/pymysql/connections.py", line 361, in __init__
    self.connect()
  File "/opt/miniconda3/envs/website/lib/python3.11/site-packages/pymysql/connections.py", line 669, in connect
    self._request_authentication()
  File "/opt/miniconda3/envs/website/lib/python3.11/site-packages/pymysql/connections.py", line 957, in _request_authentication
    auth_packet = self._read_packet()
                  ^^^^^^^^^^^^^^^^^^^
  File "/opt/miniconda3/envs/website/lib/python3.11/site-packages/pymysql/connections.py", line 775, in _read_packet
    packet.raise_for_error()
  File "/opt/miniconda3/envs/website/lib/python3.11/site-packages/pymysql/protocol.py", line 219, in raise_for_error
    err.raise_mysql_exception(self._data)
  File "/opt/miniconda3/envs/website/lib/python3.11/site-packages/pymysql/err.py", line 150, in raise_mysql_exception
    raise errorclass(errno, errval)
django.db.utils.OperationalError: (1698, "Access denied for user 'root'@'localhost'")
Not Found: /shell
Not Found: /shell
Not Found: /shell
Not Found: /webui/
Not Found: /geoserver/web/
Internal Server Error: /forum/course_resources/
Traceback (most recent call last):
  File "/opt/miniconda3/envs/website/lib/python3.11/site-packages/django/db/backends/base/base.py", line 282, in ensure_connection
    self.connect()
  File "/opt/miniconda3/envs/website/lib/python3.11/site-packages/django/utils/asyncio.py", line 26, in inner
    return func(*args, **kwargs)
           ^^^^^^^^^^^^^^^^^^^^^
  File "/opt/miniconda3/envs/website/lib/python3.11/site-packages/django/db/backends/base/base.py", line 263, in connect
    self.connection = self.get_new_connection(conn_params)
                      ^^^^^^^^^^^^^^^^^^^^^^^^^^^^^^^^^^^^
  File "/opt/miniconda3/envs/website/lib/python3.11/site-packages/django/utils/asyncio.py", line 26, in inner
    return func(*args, **kwargs)
           ^^^^^^^^^^^^^^^^^^^^^
  File "/opt/miniconda3/envs/website/lib/python3.11/site-packages/django/db/backends/mysql/base.py", line 247, in get_new_connection
    connection = Database.connect(**conn_params)
                 ^^^^^^^^^^^^^^^^^^^^^^^^^^^^^^^
  File "/opt/miniconda3/envs/website/lib/python3.11/site-packages/pymysql/connections.py", line 361, in __init__
    self.connect()
  File "/opt/miniconda3/envs/website/lib/python3.11/site-packages/pymysql/connections.py", line 669, in connect
    self._request_authentication()
  File "/opt/miniconda3/envs/website/lib/python3.11/site-packages/pymysql/connections.py", line 957, in _request_authentication
    auth_packet = self._read_packet()
                  ^^^^^^^^^^^^^^^^^^^
  File "/opt/miniconda3/envs/website/lib/python3.11/site-packages/pymysql/connections.py", line 775, in _read_packet
    packet.raise_for_error()
  File "/opt/miniconda3/envs/website/lib/python3.11/site-packages/pymysql/protocol.py", line 219, in raise_for_error
    err.raise_mysql_exception(self._data)
  File "/opt/miniconda3/envs/website/lib/python3.11/site-packages/pymysql/err.py", line 150, in raise_mysql_exception
    raise errorclass(errno, errval)
pymysql.err.OperationalError: (1698, "Access denied for user 'root'@'localhost'")

The above exception was the direct cause of the following exception:

Traceback (most recent call last):
  File "/opt/miniconda3/envs/website/lib/python3.11/site-packages/django/core/handlers/exception.py", line 55, in inner
    response = get_response(request)
               ^^^^^^^^^^^^^^^^^^^^^
  File "/opt/miniconda3/envs/website/lib/python3.11/site-packages/django/core/handlers/base.py", line 197, in _get_response
    response = wrapped_callback(request, *callback_args, **callback_kwargs)
               ^^^^^^^^^^^^^^^^^^^^^^^^^^^^^^^^^^^^^^^^^^^^^^^^^^^^^^^^^^^^
  File "/home/scs22/iGEM-2024-Coders/USTC-Software/Apps/forum/views.py", line 106, in course_resources_index
    page_obj = paginator.get_page(page_number)
               ^^^^^^^^^^^^^^^^^^^^^^^^^^^^^^^
  File "/opt/miniconda3/envs/website/lib/python3.11/site-packages/django/core/paginator.py", line 66, in get_page
    number = self.validate_number(number)
             ^^^^^^^^^^^^^^^^^^^^^^^^^^^^
  File "/opt/miniconda3/envs/website/lib/python3.11/site-packages/django/core/paginator.py", line 53, in validate_number
    if number > self.num_pages:
                ^^^^^^^^^^^^^^
  File "/opt/miniconda3/envs/website/lib/python3.11/site-packages/django/utils/functional.py", line 57, in __get__
    res = instance.__dict__[self.name] = self.func(instance)
                                         ^^^^^^^^^^^^^^^^^^^
  File "/opt/miniconda3/envs/website/lib/python3.11/site-packages/django/core/paginator.py", line 102, in num_pages
    if self.count == 0 and not self.allow_empty_first_page:
       ^^^^^^^^^^
  File "/opt/miniconda3/envs/website/lib/python3.11/site-packages/django/utils/functional.py", line 57, in __get__
    res = instance.__dict__[self.name] = self.func(instance)
                                         ^^^^^^^^^^^^^^^^^^^
  File "/opt/miniconda3/envs/website/lib/python3.11/site-packages/django/core/paginator.py", line 96, in count
    return c()
           ^^^
  File "/opt/miniconda3/envs/website/lib/python3.11/site-packages/django/db/models/query.py", line 621, in count
    return self.query.get_count(using=self.db)
           ^^^^^^^^^^^^^^^^^^^^^^^^^^^^^^^^^^^
  File "/opt/miniconda3/envs/website/lib/python3.11/site-packages/django/db/models/sql/query.py", line 559, in get_count
    return obj.get_aggregation(using, ["__count"])["__count"]
           ^^^^^^^^^^^^^^^^^^^^^^^^^^^^^^^^^^^^^^^
  File "/opt/miniconda3/envs/website/lib/python3.11/site-packages/django/db/models/sql/query.py", line 544, in get_aggregation
    result = compiler.execute_sql(SINGLE)
             ^^^^^^^^^^^^^^^^^^^^^^^^^^^^
  File "/opt/miniconda3/envs/website/lib/python3.11/site-packages/django/db/models/sql/compiler.py", line 1393, in execute_sql
    cursor = self.connection.cursor()
             ^^^^^^^^^^^^^^^^^^^^^^^^
  File "/opt/miniconda3/envs/website/lib/python3.11/site-packages/django/utils/asyncio.py", line 26, in inner
    return func(*args, **kwargs)
           ^^^^^^^^^^^^^^^^^^^^^
  File "/opt/miniconda3/envs/website/lib/python3.11/site-packages/django/db/backends/base/base.py", line 323, in cursor
    return self._cursor()
           ^^^^^^^^^^^^^^
  File "/opt/miniconda3/envs/website/lib/python3.11/site-packages/django/db/backends/base/base.py", line 299, in _cursor
    self.ensure_connection()
  File "/opt/miniconda3/envs/website/lib/python3.11/site-packages/django/utils/asyncio.py", line 26, in inner
    return func(*args, **kwargs)
           ^^^^^^^^^^^^^^^^^^^^^
  File "/opt/miniconda3/envs/website/lib/python3.11/site-packages/django/db/backends/base/base.py", line 281, in ensure_connection
    with self.wrap_database_errors:
  File "/opt/miniconda3/envs/website/lib/python3.11/site-packages/django/db/utils.py", line 91, in __exit__
    raise dj_exc_value.with_traceback(traceback) from exc_value
  File "/opt/miniconda3/envs/website/lib/python3.11/site-packages/django/db/backends/base/base.py", line 282, in ensure_connection
    self.connect()
  File "/opt/miniconda3/envs/website/lib/python3.11/site-packages/django/utils/asyncio.py", line 26, in inner
    return func(*args, **kwargs)
           ^^^^^^^^^^^^^^^^^^^^^
  File "/opt/miniconda3/envs/website/lib/python3.11/site-packages/django/db/backends/base/base.py", line 263, in connect
    self.connection = self.get_new_connection(conn_params)
                      ^^^^^^^^^^^^^^^^^^^^^^^^^^^^^^^^^^^^
  File "/opt/miniconda3/envs/website/lib/python3.11/site-packages/django/utils/asyncio.py", line 26, in inner
    return func(*args, **kwargs)
           ^^^^^^^^^^^^^^^^^^^^^
  File "/opt/miniconda3/envs/website/lib/python3.11/site-packages/django/db/backends/mysql/base.py", line 247, in get_new_connection
    connection = Database.connect(**conn_params)
                 ^^^^^^^^^^^^^^^^^^^^^^^^^^^^^^^
  File "/opt/miniconda3/envs/website/lib/python3.11/site-packages/pymysql/connections.py", line 361, in __init__
    self.connect()
  File "/opt/miniconda3/envs/website/lib/python3.11/site-packages/pymysql/connections.py", line 669, in connect
    self._request_authentication()
  File "/opt/miniconda3/envs/website/lib/python3.11/site-packages/pymysql/connections.py", line 957, in _request_authentication
    auth_packet = self._read_packet()
                  ^^^^^^^^^^^^^^^^^^^
  File "/opt/miniconda3/envs/website/lib/python3.11/site-packages/pymysql/connections.py", line 775, in _read_packet
    packet.raise_for_error()
  File "/opt/miniconda3/envs/website/lib/python3.11/site-packages/pymysql/protocol.py", line 219, in raise_for_error
    err.raise_mysql_exception(self._data)
  File "/opt/miniconda3/envs/website/lib/python3.11/site-packages/pymysql/err.py", line 150, in raise_mysql_exception
    raise errorclass(errno, errval)
django.db.utils.OperationalError: (1698, "Access denied for user 'root'@'localhost'")
Internal Server Error: /forum/forum_index/
Traceback (most recent call last):
  File "/opt/miniconda3/envs/website/lib/python3.11/site-packages/django/db/backends/base/base.py", line 282, in ensure_connection
    self.connect()
  File "/opt/miniconda3/envs/website/lib/python3.11/site-packages/django/utils/asyncio.py", line 26, in inner
    return func(*args, **kwargs)
           ^^^^^^^^^^^^^^^^^^^^^
  File "/opt/miniconda3/envs/website/lib/python3.11/site-packages/django/db/backends/base/base.py", line 263, in connect
    self.connection = self.get_new_connection(conn_params)
                      ^^^^^^^^^^^^^^^^^^^^^^^^^^^^^^^^^^^^
  File "/opt/miniconda3/envs/website/lib/python3.11/site-packages/django/utils/asyncio.py", line 26, in inner
    return func(*args, **kwargs)
           ^^^^^^^^^^^^^^^^^^^^^
  File "/opt/miniconda3/envs/website/lib/python3.11/site-packages/django/db/backends/mysql/base.py", line 247, in get_new_connection
    connection = Database.connect(**conn_params)
                 ^^^^^^^^^^^^^^^^^^^^^^^^^^^^^^^
  File "/opt/miniconda3/envs/website/lib/python3.11/site-packages/pymysql/connections.py", line 361, in __init__
    self.connect()
  File "/opt/miniconda3/envs/website/lib/python3.11/site-packages/pymysql/connections.py", line 669, in connect
    self._request_authentication()
  File "/opt/miniconda3/envs/website/lib/python3.11/site-packages/pymysql/connections.py", line 957, in _request_authentication
    auth_packet = self._read_packet()
                  ^^^^^^^^^^^^^^^^^^^
  File "/opt/miniconda3/envs/website/lib/python3.11/site-packages/pymysql/connections.py", line 775, in _read_packet
    packet.raise_for_error()
  File "/opt/miniconda3/envs/website/lib/python3.11/site-packages/pymysql/protocol.py", line 219, in raise_for_error
    err.raise_mysql_exception(self._data)
  File "/opt/miniconda3/envs/website/lib/python3.11/site-packages/pymysql/err.py", line 150, in raise_mysql_exception
    raise errorclass(errno, errval)
pymysql.err.OperationalError: (1698, "Access denied for user 'root'@'localhost'")

The above exception was the direct cause of the following exception:

Traceback (most recent call last):
  File "/opt/miniconda3/envs/website/lib/python3.11/site-packages/django/core/handlers/exception.py", line 55, in inner
    response = get_response(request)
               ^^^^^^^^^^^^^^^^^^^^^
  File "/opt/miniconda3/envs/website/lib/python3.11/site-packages/django/core/handlers/base.py", line 197, in _get_response
    response = wrapped_callback(request, *callback_args, **callback_kwargs)
               ^^^^^^^^^^^^^^^^^^^^^^^^^^^^^^^^^^^^^^^^^^^^^^^^^^^^^^^^^^^^
  File "/home/scs22/iGEM-2024-Coders/USTC-Software/Apps/forum/views.py", line 14, in forum_index
    posts_data = post.get_all_posts(page=int(page_number), items_per_page=items_per_page)
                 ^^^^^^^^^^^^^^^^^^^^^^^^^^^^^^^^^^^^^^^^^^^^^^^^^^^^^^^^^^^^^^^^^^^^^^^^
  File "/home/scs22/iGEM-2024-Coders/USTC-Software/Apps/forum/models.py", line 106, in get_all_posts
    page_obj = paginator.get_page(page)
               ^^^^^^^^^^^^^^^^^^^^^^^^
  File "/opt/miniconda3/envs/website/lib/python3.11/site-packages/django/core/paginator.py", line 66, in get_page
    number = self.validate_number(number)
             ^^^^^^^^^^^^^^^^^^^^^^^^^^^^
  File "/opt/miniconda3/envs/website/lib/python3.11/site-packages/django/core/paginator.py", line 53, in validate_number
    if number > self.num_pages:
                ^^^^^^^^^^^^^^
  File "/opt/miniconda3/envs/website/lib/python3.11/site-packages/django/utils/functional.py", line 57, in __get__
    res = instance.__dict__[self.name] = self.func(instance)
                                         ^^^^^^^^^^^^^^^^^^^
  File "/opt/miniconda3/envs/website/lib/python3.11/site-packages/django/core/paginator.py", line 102, in num_pages
    if self.count == 0 and not self.allow_empty_first_page:
       ^^^^^^^^^^
  File "/opt/miniconda3/envs/website/lib/python3.11/site-packages/django/utils/functional.py", line 57, in __get__
    res = instance.__dict__[self.name] = self.func(instance)
                                         ^^^^^^^^^^^^^^^^^^^
  File "/opt/miniconda3/envs/website/lib/python3.11/site-packages/django/core/paginator.py", line 96, in count
    return c()
           ^^^
  File "/opt/miniconda3/envs/website/lib/python3.11/site-packages/django/db/models/query.py", line 621, in count
    return self.query.get_count(using=self.db)
           ^^^^^^^^^^^^^^^^^^^^^^^^^^^^^^^^^^^
  File "/opt/miniconda3/envs/website/lib/python3.11/site-packages/django/db/models/sql/query.py", line 559, in get_count
    return obj.get_aggregation(using, ["__count"])["__count"]
           ^^^^^^^^^^^^^^^^^^^^^^^^^^^^^^^^^^^^^^^
  File "/opt/miniconda3/envs/website/lib/python3.11/site-packages/django/db/models/sql/query.py", line 544, in get_aggregation
    result = compiler.execute_sql(SINGLE)
             ^^^^^^^^^^^^^^^^^^^^^^^^^^^^
  File "/opt/miniconda3/envs/website/lib/python3.11/site-packages/django/db/models/sql/compiler.py", line 1393, in execute_sql
    cursor = self.connection.cursor()
             ^^^^^^^^^^^^^^^^^^^^^^^^
  File "/opt/miniconda3/envs/website/lib/python3.11/site-packages/django/utils/asyncio.py", line 26, in inner
    return func(*args, **kwargs)
           ^^^^^^^^^^^^^^^^^^^^^
  File "/opt/miniconda3/envs/website/lib/python3.11/site-packages/django/db/backends/base/base.py", line 323, in cursor
    return self._cursor()
           ^^^^^^^^^^^^^^
  File "/opt/miniconda3/envs/website/lib/python3.11/site-packages/django/db/backends/base/base.py", line 299, in _cursor
    self.ensure_connection()
  File "/opt/miniconda3/envs/website/lib/python3.11/site-packages/django/utils/asyncio.py", line 26, in inner
    return func(*args, **kwargs)
           ^^^^^^^^^^^^^^^^^^^^^
  File "/opt/miniconda3/envs/website/lib/python3.11/site-packages/django/db/backends/base/base.py", line 281, in ensure_connection
    with self.wrap_database_errors:
  File "/opt/miniconda3/envs/website/lib/python3.11/site-packages/django/db/utils.py", line 91, in __exit__
    raise dj_exc_value.with_traceback(traceback) from exc_value
  File "/opt/miniconda3/envs/website/lib/python3.11/site-packages/django/db/backends/base/base.py", line 282, in ensure_connection
    self.connect()
  File "/opt/miniconda3/envs/website/lib/python3.11/site-packages/django/utils/asyncio.py", line 26, in inner
    return func(*args, **kwargs)
           ^^^^^^^^^^^^^^^^^^^^^
  File "/opt/miniconda3/envs/website/lib/python3.11/site-packages/django/db/backends/base/base.py", line 263, in connect
    self.connection = self.get_new_connection(conn_params)
                      ^^^^^^^^^^^^^^^^^^^^^^^^^^^^^^^^^^^^
  File "/opt/miniconda3/envs/website/lib/python3.11/site-packages/django/utils/asyncio.py", line 26, in inner
    return func(*args, **kwargs)
           ^^^^^^^^^^^^^^^^^^^^^
  File "/opt/miniconda3/envs/website/lib/python3.11/site-packages/django/db/backends/mysql/base.py", line 247, in get_new_connection
    connection = Database.connect(**conn_params)
                 ^^^^^^^^^^^^^^^^^^^^^^^^^^^^^^^
  File "/opt/miniconda3/envs/website/lib/python3.11/site-packages/pymysql/connections.py", line 361, in __init__
    self.connect()
  File "/opt/miniconda3/envs/website/lib/python3.11/site-packages/pymysql/connections.py", line 669, in connect
    self._request_authentication()
  File "/opt/miniconda3/envs/website/lib/python3.11/site-packages/pymysql/connections.py", line 957, in _request_authentication
    auth_packet = self._read_packet()
                  ^^^^^^^^^^^^^^^^^^^
  File "/opt/miniconda3/envs/website/lib/python3.11/site-packages/pymysql/connections.py", line 775, in _read_packet
    packet.raise_for_error()
  File "/opt/miniconda3/envs/website/lib/python3.11/site-packages/pymysql/protocol.py", line 219, in raise_for_error
    err.raise_mysql_exception(self._data)
  File "/opt/miniconda3/envs/website/lib/python3.11/site-packages/pymysql/err.py", line 150, in raise_mysql_exception
    raise errorclass(errno, errval)
django.db.utils.OperationalError: (1698, "Access denied for user 'root'@'localhost'")
Not Found: /shell
Not Found: /shell
Internal Server Error: /forum/course_resources/
Traceback (most recent call last):
  File "/opt/miniconda3/envs/website/lib/python3.11/site-packages/django/db/backends/base/base.py", line 282, in ensure_connection
    self.connect()
  File "/opt/miniconda3/envs/website/lib/python3.11/site-packages/django/utils/asyncio.py", line 26, in inner
    return func(*args, **kwargs)
           ^^^^^^^^^^^^^^^^^^^^^
  File "/opt/miniconda3/envs/website/lib/python3.11/site-packages/django/db/backends/base/base.py", line 263, in connect
    self.connection = self.get_new_connection(conn_params)
                      ^^^^^^^^^^^^^^^^^^^^^^^^^^^^^^^^^^^^
  File "/opt/miniconda3/envs/website/lib/python3.11/site-packages/django/utils/asyncio.py", line 26, in inner
    return func(*args, **kwargs)
           ^^^^^^^^^^^^^^^^^^^^^
  File "/opt/miniconda3/envs/website/lib/python3.11/site-packages/django/db/backends/mysql/base.py", line 247, in get_new_connection
    connection = Database.connect(**conn_params)
                 ^^^^^^^^^^^^^^^^^^^^^^^^^^^^^^^
  File "/opt/miniconda3/envs/website/lib/python3.11/site-packages/pymysql/connections.py", line 361, in __init__
    self.connect()
  File "/opt/miniconda3/envs/website/lib/python3.11/site-packages/pymysql/connections.py", line 669, in connect
    self._request_authentication()
  File "/opt/miniconda3/envs/website/lib/python3.11/site-packages/pymysql/connections.py", line 957, in _request_authentication
    auth_packet = self._read_packet()
                  ^^^^^^^^^^^^^^^^^^^
  File "/opt/miniconda3/envs/website/lib/python3.11/site-packages/pymysql/connections.py", line 775, in _read_packet
    packet.raise_for_error()
  File "/opt/miniconda3/envs/website/lib/python3.11/site-packages/pymysql/protocol.py", line 219, in raise_for_error
    err.raise_mysql_exception(self._data)
  File "/opt/miniconda3/envs/website/lib/python3.11/site-packages/pymysql/err.py", line 150, in raise_mysql_exception
    raise errorclass(errno, errval)
pymysql.err.OperationalError: (1698, "Access denied for user 'root'@'localhost'")

The above exception was the direct cause of the following exception:

Traceback (most recent call last):
  File "/opt/miniconda3/envs/website/lib/python3.11/site-packages/django/core/handlers/exception.py", line 55, in inner
    response = get_response(request)
               ^^^^^^^^^^^^^^^^^^^^^
  File "/opt/miniconda3/envs/website/lib/python3.11/site-packages/django/core/handlers/base.py", line 197, in _get_response
    response = wrapped_callback(request, *callback_args, **callback_kwargs)
               ^^^^^^^^^^^^^^^^^^^^^^^^^^^^^^^^^^^^^^^^^^^^^^^^^^^^^^^^^^^^
  File "/home/scs22/iGEM-2024-Coders/USTC-Software/Apps/forum/views.py", line 106, in course_resources_index
    page_obj = paginator.get_page(page_number)
               ^^^^^^^^^^^^^^^^^^^^^^^^^^^^^^^
  File "/opt/miniconda3/envs/website/lib/python3.11/site-packages/django/core/paginator.py", line 66, in get_page
    number = self.validate_number(number)
             ^^^^^^^^^^^^^^^^^^^^^^^^^^^^
  File "/opt/miniconda3/envs/website/lib/python3.11/site-packages/django/core/paginator.py", line 53, in validate_number
    if number > self.num_pages:
                ^^^^^^^^^^^^^^
  File "/opt/miniconda3/envs/website/lib/python3.11/site-packages/django/utils/functional.py", line 57, in __get__
    res = instance.__dict__[self.name] = self.func(instance)
                                         ^^^^^^^^^^^^^^^^^^^
  File "/opt/miniconda3/envs/website/lib/python3.11/site-packages/django/core/paginator.py", line 102, in num_pages
    if self.count == 0 and not self.allow_empty_first_page:
       ^^^^^^^^^^
  File "/opt/miniconda3/envs/website/lib/python3.11/site-packages/django/utils/functional.py", line 57, in __get__
    res = instance.__dict__[self.name] = self.func(instance)
                                         ^^^^^^^^^^^^^^^^^^^
  File "/opt/miniconda3/envs/website/lib/python3.11/site-packages/django/core/paginator.py", line 96, in count
    return c()
           ^^^
  File "/opt/miniconda3/envs/website/lib/python3.11/site-packages/django/db/models/query.py", line 621, in count
    return self.query.get_count(using=self.db)
           ^^^^^^^^^^^^^^^^^^^^^^^^^^^^^^^^^^^
  File "/opt/miniconda3/envs/website/lib/python3.11/site-packages/django/db/models/sql/query.py", line 559, in get_count
    return obj.get_aggregation(using, ["__count"])["__count"]
           ^^^^^^^^^^^^^^^^^^^^^^^^^^^^^^^^^^^^^^^
  File "/opt/miniconda3/envs/website/lib/python3.11/site-packages/django/db/models/sql/query.py", line 544, in get_aggregation
    result = compiler.execute_sql(SINGLE)
             ^^^^^^^^^^^^^^^^^^^^^^^^^^^^
  File "/opt/miniconda3/envs/website/lib/python3.11/site-packages/django/db/models/sql/compiler.py", line 1393, in execute_sql
    cursor = self.connection.cursor()
             ^^^^^^^^^^^^^^^^^^^^^^^^
  File "/opt/miniconda3/envs/website/lib/python3.11/site-packages/django/utils/asyncio.py", line 26, in inner
    return func(*args, **kwargs)
           ^^^^^^^^^^^^^^^^^^^^^
  File "/opt/miniconda3/envs/website/lib/python3.11/site-packages/django/db/backends/base/base.py", line 323, in cursor
    return self._cursor()
           ^^^^^^^^^^^^^^
  File "/opt/miniconda3/envs/website/lib/python3.11/site-packages/django/db/backends/base/base.py", line 299, in _cursor
    self.ensure_connection()
  File "/opt/miniconda3/envs/website/lib/python3.11/site-packages/django/utils/asyncio.py", line 26, in inner
    return func(*args, **kwargs)
           ^^^^^^^^^^^^^^^^^^^^^
  File "/opt/miniconda3/envs/website/lib/python3.11/site-packages/django/db/backends/base/base.py", line 281, in ensure_connection
    with self.wrap_database_errors:
  File "/opt/miniconda3/envs/website/lib/python3.11/site-packages/django/db/utils.py", line 91, in __exit__
    raise dj_exc_value.with_traceback(traceback) from exc_value
  File "/opt/miniconda3/envs/website/lib/python3.11/site-packages/django/db/backends/base/base.py", line 282, in ensure_connection
    self.connect()
  File "/opt/miniconda3/envs/website/lib/python3.11/site-packages/django/utils/asyncio.py", line 26, in inner
    return func(*args, **kwargs)
           ^^^^^^^^^^^^^^^^^^^^^
  File "/opt/miniconda3/envs/website/lib/python3.11/site-packages/django/db/backends/base/base.py", line 263, in connect
    self.connection = self.get_new_connection(conn_params)
                      ^^^^^^^^^^^^^^^^^^^^^^^^^^^^^^^^^^^^
  File "/opt/miniconda3/envs/website/lib/python3.11/site-packages/django/utils/asyncio.py", line 26, in inner
    return func(*args, **kwargs)
           ^^^^^^^^^^^^^^^^^^^^^
  File "/opt/miniconda3/envs/website/lib/python3.11/site-packages/django/db/backends/mysql/base.py", line 247, in get_new_connection
    connection = Database.connect(**conn_params)
                 ^^^^^^^^^^^^^^^^^^^^^^^^^^^^^^^
  File "/opt/miniconda3/envs/website/lib/python3.11/site-packages/pymysql/connections.py", line 361, in __init__
    self.connect()
  File "/opt/miniconda3/envs/website/lib/python3.11/site-packages/pymysql/connections.py", line 669, in connect
    self._request_authentication()
  File "/opt/miniconda3/envs/website/lib/python3.11/site-packages/pymysql/connections.py", line 957, in _request_authentication
    auth_packet = self._read_packet()
                  ^^^^^^^^^^^^^^^^^^^
  File "/opt/miniconda3/envs/website/lib/python3.11/site-packages/pymysql/connections.py", line 775, in _read_packet
    packet.raise_for_error()
  File "/opt/miniconda3/envs/website/lib/python3.11/site-packages/pymysql/protocol.py", line 219, in raise_for_error
    err.raise_mysql_exception(self._data)
  File "/opt/miniconda3/envs/website/lib/python3.11/site-packages/pymysql/err.py", line 150, in raise_mysql_exception
    raise errorclass(errno, errval)
django.db.utils.OperationalError: (1698, "Access denied for user 'root'@'localhost'")
Internal Server Error: /forum/forum_index/
Traceback (most recent call last):
  File "/opt/miniconda3/envs/website/lib/python3.11/site-packages/django/db/backends/base/base.py", line 282, in ensure_connection
    self.connect()
  File "/opt/miniconda3/envs/website/lib/python3.11/site-packages/django/utils/asyncio.py", line 26, in inner
    return func(*args, **kwargs)
           ^^^^^^^^^^^^^^^^^^^^^
  File "/opt/miniconda3/envs/website/lib/python3.11/site-packages/django/db/backends/base/base.py", line 263, in connect
    self.connection = self.get_new_connection(conn_params)
                      ^^^^^^^^^^^^^^^^^^^^^^^^^^^^^^^^^^^^
  File "/opt/miniconda3/envs/website/lib/python3.11/site-packages/django/utils/asyncio.py", line 26, in inner
    return func(*args, **kwargs)
           ^^^^^^^^^^^^^^^^^^^^^
  File "/opt/miniconda3/envs/website/lib/python3.11/site-packages/django/db/backends/mysql/base.py", line 247, in get_new_connection
    connection = Database.connect(**conn_params)
                 ^^^^^^^^^^^^^^^^^^^^^^^^^^^^^^^
  File "/opt/miniconda3/envs/website/lib/python3.11/site-packages/pymysql/connections.py", line 361, in __init__
    self.connect()
  File "/opt/miniconda3/envs/website/lib/python3.11/site-packages/pymysql/connections.py", line 669, in connect
    self._request_authentication()
  File "/opt/miniconda3/envs/website/lib/python3.11/site-packages/pymysql/connections.py", line 957, in _request_authentication
    auth_packet = self._read_packet()
                  ^^^^^^^^^^^^^^^^^^^
  File "/opt/miniconda3/envs/website/lib/python3.11/site-packages/pymysql/connections.py", line 775, in _read_packet
    packet.raise_for_error()
  File "/opt/miniconda3/envs/website/lib/python3.11/site-packages/pymysql/protocol.py", line 219, in raise_for_error
    err.raise_mysql_exception(self._data)
  File "/opt/miniconda3/envs/website/lib/python3.11/site-packages/pymysql/err.py", line 150, in raise_mysql_exception
    raise errorclass(errno, errval)
pymysql.err.OperationalError: (1698, "Access denied for user 'root'@'localhost'")

The above exception was the direct cause of the following exception:

Traceback (most recent call last):
  File "/opt/miniconda3/envs/website/lib/python3.11/site-packages/django/core/handlers/exception.py", line 55, in inner
    response = get_response(request)
               ^^^^^^^^^^^^^^^^^^^^^
  File "/opt/miniconda3/envs/website/lib/python3.11/site-packages/django/core/handlers/base.py", line 197, in _get_response
    response = wrapped_callback(request, *callback_args, **callback_kwargs)
               ^^^^^^^^^^^^^^^^^^^^^^^^^^^^^^^^^^^^^^^^^^^^^^^^^^^^^^^^^^^^
  File "/home/scs22/iGEM-2024-Coders/USTC-Software/Apps/forum/views.py", line 14, in forum_index
    posts_data = post.get_all_posts(page=int(page_number), items_per_page=items_per_page)
                 ^^^^^^^^^^^^^^^^^^^^^^^^^^^^^^^^^^^^^^^^^^^^^^^^^^^^^^^^^^^^^^^^^^^^^^^^
  File "/home/scs22/iGEM-2024-Coders/USTC-Software/Apps/forum/models.py", line 106, in get_all_posts
    page_obj = paginator.get_page(page)
               ^^^^^^^^^^^^^^^^^^^^^^^^
  File "/opt/miniconda3/envs/website/lib/python3.11/site-packages/django/core/paginator.py", line 66, in get_page
    number = self.validate_number(number)
             ^^^^^^^^^^^^^^^^^^^^^^^^^^^^
  File "/opt/miniconda3/envs/website/lib/python3.11/site-packages/django/core/paginator.py", line 53, in validate_number
    if number > self.num_pages:
                ^^^^^^^^^^^^^^
  File "/opt/miniconda3/envs/website/lib/python3.11/site-packages/django/utils/functional.py", line 57, in __get__
    res = instance.__dict__[self.name] = self.func(instance)
                                         ^^^^^^^^^^^^^^^^^^^
  File "/opt/miniconda3/envs/website/lib/python3.11/site-packages/django/core/paginator.py", line 102, in num_pages
    if self.count == 0 and not self.allow_empty_first_page:
       ^^^^^^^^^^
  File "/opt/miniconda3/envs/website/lib/python3.11/site-packages/django/utils/functional.py", line 57, in __get__
    res = instance.__dict__[self.name] = self.func(instance)
                                         ^^^^^^^^^^^^^^^^^^^
  File "/opt/miniconda3/envs/website/lib/python3.11/site-packages/django/core/paginator.py", line 96, in count
    return c()
           ^^^
  File "/opt/miniconda3/envs/website/lib/python3.11/site-packages/django/db/models/query.py", line 621, in count
    return self.query.get_count(using=self.db)
           ^^^^^^^^^^^^^^^^^^^^^^^^^^^^^^^^^^^
  File "/opt/miniconda3/envs/website/lib/python3.11/site-packages/django/db/models/sql/query.py", line 559, in get_count
    return obj.get_aggregation(using, ["__count"])["__count"]
           ^^^^^^^^^^^^^^^^^^^^^^^^^^^^^^^^^^^^^^^
  File "/opt/miniconda3/envs/website/lib/python3.11/site-packages/django/db/models/sql/query.py", line 544, in get_aggregation
    result = compiler.execute_sql(SINGLE)
             ^^^^^^^^^^^^^^^^^^^^^^^^^^^^
  File "/opt/miniconda3/envs/website/lib/python3.11/site-packages/django/db/models/sql/compiler.py", line 1393, in execute_sql
    cursor = self.connection.cursor()
             ^^^^^^^^^^^^^^^^^^^^^^^^
  File "/opt/miniconda3/envs/website/lib/python3.11/site-packages/django/utils/asyncio.py", line 26, in inner
    return func(*args, **kwargs)
           ^^^^^^^^^^^^^^^^^^^^^
  File "/opt/miniconda3/envs/website/lib/python3.11/site-packages/django/db/backends/base/base.py", line 323, in cursor
    return self._cursor()
           ^^^^^^^^^^^^^^
  File "/opt/miniconda3/envs/website/lib/python3.11/site-packages/django/db/backends/base/base.py", line 299, in _cursor
    self.ensure_connection()
  File "/opt/miniconda3/envs/website/lib/python3.11/site-packages/django/utils/asyncio.py", line 26, in inner
    return func(*args, **kwargs)
           ^^^^^^^^^^^^^^^^^^^^^
  File "/opt/miniconda3/envs/website/lib/python3.11/site-packages/django/db/backends/base/base.py", line 281, in ensure_connection
    with self.wrap_database_errors:
  File "/opt/miniconda3/envs/website/lib/python3.11/site-packages/django/db/utils.py", line 91, in __exit__
    raise dj_exc_value.with_traceback(traceback) from exc_value
  File "/opt/miniconda3/envs/website/lib/python3.11/site-packages/django/db/backends/base/base.py", line 282, in ensure_connection
    self.connect()
  File "/opt/miniconda3/envs/website/lib/python3.11/site-packages/django/utils/asyncio.py", line 26, in inner
    return func(*args, **kwargs)
           ^^^^^^^^^^^^^^^^^^^^^
  File "/opt/miniconda3/envs/website/lib/python3.11/site-packages/django/db/backends/base/base.py", line 263, in connect
    self.connection = self.get_new_connection(conn_params)
                      ^^^^^^^^^^^^^^^^^^^^^^^^^^^^^^^^^^^^
  File "/opt/miniconda3/envs/website/lib/python3.11/site-packages/django/utils/asyncio.py", line 26, in inner
    return func(*args, **kwargs)
           ^^^^^^^^^^^^^^^^^^^^^
  File "/opt/miniconda3/envs/website/lib/python3.11/site-packages/django/db/backends/mysql/base.py", line 247, in get_new_connection
    connection = Database.connect(**conn_params)
                 ^^^^^^^^^^^^^^^^^^^^^^^^^^^^^^^
  File "/opt/miniconda3/envs/website/lib/python3.11/site-packages/pymysql/connections.py", line 361, in __init__
    self.connect()
  File "/opt/miniconda3/envs/website/lib/python3.11/site-packages/pymysql/connections.py", line 669, in connect
    self._request_authentication()
  File "/opt/miniconda3/envs/website/lib/python3.11/site-packages/pymysql/connections.py", line 957, in _request_authentication
    auth_packet = self._read_packet()
                  ^^^^^^^^^^^^^^^^^^^
  File "/opt/miniconda3/envs/website/lib/python3.11/site-packages/pymysql/connections.py", line 775, in _read_packet
    packet.raise_for_error()
  File "/opt/miniconda3/envs/website/lib/python3.11/site-packages/pymysql/protocol.py", line 219, in raise_for_error
    err.raise_mysql_exception(self._data)
  File "/opt/miniconda3/envs/website/lib/python3.11/site-packages/pymysql/err.py", line 150, in raise_mysql_exception
    raise errorclass(errno, errval)
django.db.utils.OperationalError: (1698, "Access denied for user 'root'@'localhost'")
Not Found: /cgi-bin/luci/;stok=/locale
Not Found: /odinhttpcall1724137395
Not Found: /sdk
Not Found: /HNAP1
Not Found: /evox/about
Not Found: /v2/_catalog
Not Found: /cgi-bin/authLogin.cgi
Not Found: /query
Not Found: /odinhttpcall1724138508
Not Found: /sdk
Not Found: /HNAP1
Not Found: /evox/about
Not Found: /solr/admin/info/system
Not Found: /solr/admin/cores
Not Found: /query
Not Found: /v2/_catalog
Internal Server Error: /forum/forum_index/
Traceback (most recent call last):
  File "/opt/miniconda3/envs/website/lib/python3.11/site-packages/django/db/backends/base/base.py", line 282, in ensure_connection
    self.connect()
  File "/opt/miniconda3/envs/website/lib/python3.11/site-packages/django/utils/asyncio.py", line 26, in inner
    return func(*args, **kwargs)
           ^^^^^^^^^^^^^^^^^^^^^
  File "/opt/miniconda3/envs/website/lib/python3.11/site-packages/django/db/backends/base/base.py", line 263, in connect
    self.connection = self.get_new_connection(conn_params)
                      ^^^^^^^^^^^^^^^^^^^^^^^^^^^^^^^^^^^^
  File "/opt/miniconda3/envs/website/lib/python3.11/site-packages/django/utils/asyncio.py", line 26, in inner
    return func(*args, **kwargs)
           ^^^^^^^^^^^^^^^^^^^^^
  File "/opt/miniconda3/envs/website/lib/python3.11/site-packages/django/db/backends/mysql/base.py", line 247, in get_new_connection
    connection = Database.connect(**conn_params)
                 ^^^^^^^^^^^^^^^^^^^^^^^^^^^^^^^
  File "/opt/miniconda3/envs/website/lib/python3.11/site-packages/pymysql/connections.py", line 361, in __init__
    self.connect()
  File "/opt/miniconda3/envs/website/lib/python3.11/site-packages/pymysql/connections.py", line 669, in connect
    self._request_authentication()
  File "/opt/miniconda3/envs/website/lib/python3.11/site-packages/pymysql/connections.py", line 957, in _request_authentication
    auth_packet = self._read_packet()
                  ^^^^^^^^^^^^^^^^^^^
  File "/opt/miniconda3/envs/website/lib/python3.11/site-packages/pymysql/connections.py", line 775, in _read_packet
    packet.raise_for_error()
  File "/opt/miniconda3/envs/website/lib/python3.11/site-packages/pymysql/protocol.py", line 219, in raise_for_error
    err.raise_mysql_exception(self._data)
  File "/opt/miniconda3/envs/website/lib/python3.11/site-packages/pymysql/err.py", line 150, in raise_mysql_exception
    raise errorclass(errno, errval)
pymysql.err.OperationalError: (1698, "Access denied for user 'root'@'localhost'")

The above exception was the direct cause of the following exception:

Traceback (most recent call last):
  File "/opt/miniconda3/envs/website/lib/python3.11/site-packages/django/core/handlers/exception.py", line 55, in inner
    response = get_response(request)
               ^^^^^^^^^^^^^^^^^^^^^
  File "/opt/miniconda3/envs/website/lib/python3.11/site-packages/django/core/handlers/base.py", line 197, in _get_response
    response = wrapped_callback(request, *callback_args, **callback_kwargs)
               ^^^^^^^^^^^^^^^^^^^^^^^^^^^^^^^^^^^^^^^^^^^^^^^^^^^^^^^^^^^^
  File "/home/scs22/iGEM-2024-Coders/USTC-Software/Apps/forum/views.py", line 14, in forum_index
    posts_data = post.get_all_posts(page=int(page_number), items_per_page=items_per_page)
                 ^^^^^^^^^^^^^^^^^^^^^^^^^^^^^^^^^^^^^^^^^^^^^^^^^^^^^^^^^^^^^^^^^^^^^^^^
  File "/home/scs22/iGEM-2024-Coders/USTC-Software/Apps/forum/models.py", line 106, in get_all_posts
    page_obj = paginator.get_page(page)
               ^^^^^^^^^^^^^^^^^^^^^^^^
  File "/opt/miniconda3/envs/website/lib/python3.11/site-packages/django/core/paginator.py", line 66, in get_page
    number = self.validate_number(number)
             ^^^^^^^^^^^^^^^^^^^^^^^^^^^^
  File "/opt/miniconda3/envs/website/lib/python3.11/site-packages/django/core/paginator.py", line 53, in validate_number
    if number > self.num_pages:
                ^^^^^^^^^^^^^^
  File "/opt/miniconda3/envs/website/lib/python3.11/site-packages/django/utils/functional.py", line 57, in __get__
    res = instance.__dict__[self.name] = self.func(instance)
                                         ^^^^^^^^^^^^^^^^^^^
  File "/opt/miniconda3/envs/website/lib/python3.11/site-packages/django/core/paginator.py", line 102, in num_pages
    if self.count == 0 and not self.allow_empty_first_page:
       ^^^^^^^^^^
  File "/opt/miniconda3/envs/website/lib/python3.11/site-packages/django/utils/functional.py", line 57, in __get__
    res = instance.__dict__[self.name] = self.func(instance)
                                         ^^^^^^^^^^^^^^^^^^^
  File "/opt/miniconda3/envs/website/lib/python3.11/site-packages/django/core/paginator.py", line 96, in count
    return c()
           ^^^
  File "/opt/miniconda3/envs/website/lib/python3.11/site-packages/django/db/models/query.py", line 621, in count
    return self.query.get_count(using=self.db)
           ^^^^^^^^^^^^^^^^^^^^^^^^^^^^^^^^^^^
  File "/opt/miniconda3/envs/website/lib/python3.11/site-packages/django/db/models/sql/query.py", line 559, in get_count
    return obj.get_aggregation(using, ["__count"])["__count"]
           ^^^^^^^^^^^^^^^^^^^^^^^^^^^^^^^^^^^^^^^
  File "/opt/miniconda3/envs/website/lib/python3.11/site-packages/django/db/models/sql/query.py", line 544, in get_aggregation
    result = compiler.execute_sql(SINGLE)
             ^^^^^^^^^^^^^^^^^^^^^^^^^^^^
  File "/opt/miniconda3/envs/website/lib/python3.11/site-packages/django/db/models/sql/compiler.py", line 1393, in execute_sql
    cursor = self.connection.cursor()
             ^^^^^^^^^^^^^^^^^^^^^^^^
  File "/opt/miniconda3/envs/website/lib/python3.11/site-packages/django/utils/asyncio.py", line 26, in inner
    return func(*args, **kwargs)
           ^^^^^^^^^^^^^^^^^^^^^
  File "/opt/miniconda3/envs/website/lib/python3.11/site-packages/django/db/backends/base/base.py", line 323, in cursor
    return self._cursor()
           ^^^^^^^^^^^^^^
  File "/opt/miniconda3/envs/website/lib/python3.11/site-packages/django/db/backends/base/base.py", line 299, in _cursor
    self.ensure_connection()
  File "/opt/miniconda3/envs/website/lib/python3.11/site-packages/django/utils/asyncio.py", line 26, in inner
    return func(*args, **kwargs)
           ^^^^^^^^^^^^^^^^^^^^^
  File "/opt/miniconda3/envs/website/lib/python3.11/site-packages/django/db/backends/base/base.py", line 281, in ensure_connection
    with self.wrap_database_errors:
  File "/opt/miniconda3/envs/website/lib/python3.11/site-packages/django/db/utils.py", line 91, in __exit__
    raise dj_exc_value.with_traceback(traceback) from exc_value
  File "/opt/miniconda3/envs/website/lib/python3.11/site-packages/django/db/backends/base/base.py", line 282, in ensure_connection
    self.connect()
  File "/opt/miniconda3/envs/website/lib/python3.11/site-packages/django/utils/asyncio.py", line 26, in inner
    return func(*args, **kwargs)
           ^^^^^^^^^^^^^^^^^^^^^
  File "/opt/miniconda3/envs/website/lib/python3.11/site-packages/django/db/backends/base/base.py", line 263, in connect
    self.connection = self.get_new_connection(conn_params)
                      ^^^^^^^^^^^^^^^^^^^^^^^^^^^^^^^^^^^^
  File "/opt/miniconda3/envs/website/lib/python3.11/site-packages/django/utils/asyncio.py", line 26, in inner
    return func(*args, **kwargs)
           ^^^^^^^^^^^^^^^^^^^^^
  File "/opt/miniconda3/envs/website/lib/python3.11/site-packages/django/db/backends/mysql/base.py", line 247, in get_new_connection
    connection = Database.connect(**conn_params)
                 ^^^^^^^^^^^^^^^^^^^^^^^^^^^^^^^
  File "/opt/miniconda3/envs/website/lib/python3.11/site-packages/pymysql/connections.py", line 361, in __init__
    self.connect()
  File "/opt/miniconda3/envs/website/lib/python3.11/site-packages/pymysql/connections.py", line 669, in connect
    self._request_authentication()
  File "/opt/miniconda3/envs/website/lib/python3.11/site-packages/pymysql/connections.py", line 957, in _request_authentication
    auth_packet = self._read_packet()
                  ^^^^^^^^^^^^^^^^^^^
  File "/opt/miniconda3/envs/website/lib/python3.11/site-packages/pymysql/connections.py", line 775, in _read_packet
    packet.raise_for_error()
  File "/opt/miniconda3/envs/website/lib/python3.11/site-packages/pymysql/protocol.py", line 219, in raise_for_error
    err.raise_mysql_exception(self._data)
  File "/opt/miniconda3/envs/website/lib/python3.11/site-packages/pymysql/err.py", line 150, in raise_mysql_exception
    raise errorclass(errno, errval)
django.db.utils.OperationalError: (1698, "Access denied for user 'root'@'localhost'")
Not Found: /shell
Not Found: /.env
Not Found: /shell
Not Found: /.env
Forbidden (CSRF cookie not set.): /
Not Found: /cgi-bin/luci/;stok=/locale
Not Found: /cgi-bin/luci/;stok=/locale
